Workbook
Name LatestScores_Class10: RawData!$BJ$6:$BJ$65

Sheet RawData
A1: Class | B1: 10
A2: Date | B2: 46118 | C2: 46119 | D2: 46120 | E2: 46120 | F2: 46121 | G2: 46122 | H2: 46126 | I2: 46126 | J2: 46128 | K2: 46129 | L2: 46128 | M2: 46129 | N2: 46131 | O2: 46133 | P2: 46133 | Q2: 46133 | R2: 46134 | S2: 46135 | T2: 46136 | U2: 46142 | V2: 46142 | W2: 46146 | X2: 46146 | Y2: 46147 | Z2: 46148 | AA2: 46149 | AB2: 46149 | AC2: 46155 | AD2: 46156 | AE2: 46157 | AF2: 46155 | AG2: 46160 | AH2: 46161 | AI2: 46161 | AJ2: 46161 | AK2: 46163 | AL2: 46163 | AM2: 46158 | AN2: 46153 | AO2: 46162 | AP2: 46153 | AQ2: 46167 | AR2: 46167 | AS2: 46167 | AT2: 46169 | AU2: 46171 | AV2: 46172 | AW2: 46170 | AX2: 46174 | AY2: 46174 | AZ2: 46177 | BA2: 46178 | BB2: 46178 | BC2: 46178 | BD2: 46177 | BE2: 46178 | BF2: 46178 | BG2: 46178 | BH2: 46179 | BI2: 46183 | BJ2: 46181
A3: Subject | B3: Science | C3: Science | D3: Science | E3: Maths | F3: Maths | G3: Science | H3: Science | I3: Science | J3: Maths | K3: Maths | L3: Science | M3: Science | N3: Science | O3: Science | P3: Science | Q3: Science | R3: Science | S3: Science | T3: Maths | U3: Science | V3: Maths | W3: Maths | X3: Science | Y3: Science | Z3: Maths | AA3: Maths | AB3: Science | AC3: Science | AD3: Science | AE3: Science | AF3: Science | AG3: Science | AH3: Science | AI3: Maths | AJ3: Maths | AK3: Maths | AL3: Science | AM3: Maths | AN3: Maths | AO3: Science | AP3: Maths | AQ3: Science | AR3: Science | AS3: Science | AT3: Science | AU3: Science | AV3: Maths | AW3: Maths | AX3: Science | AY3: Maths | AZ3: Science | BA3: Science | BB3: Science | BC3: Science | BD3: Maths | BE3: Maths | BF3: Maths | BG3: Maths | BH3: Science | BI3: Science | BJ3: Maths
A4: Total Marks | B4: 20 | C4: 50 | D4: 50 | E4: 45 | F4: 30 | G4: 40 | H4: 38 | I4: 50 | J4: 15 | K4: 40 | L4: 15 | M4: 38 | N4: 40 | O4: 40 | P4: 40 | Q4: 25 | R4: 40 | S4: 40 | T4: 30 | U4: 45 | V4: 45 | W4: 65 | X4: 38 | Y4: 40 | Z4: 45 | AA4: 45 | AB4: 38 | AC4: 38 | AD4: 54 | AE4: 45 | AF4: 40 | AG4: 53 | AH4: 50 | AI4: 35 | AJ4: 70 | AK4: 39 | AL4: 75 | AM4: 25 | AN4: 40 | AO4: 30 | AP4: 30 | AQ4: 58 | AR4: 78 | AS4: 50 | AT4: 45 | AU4: 50 | AV4: 40 | AW4: 50 | AX4: 55 | AY4: 45 | AZ4: 70 | BA4: 80 | BB4: 45 | BC4: 42 | BD4: 30 | BE4: 30 | BF4: 30 | BG4: 30 | BH4: 70 | BI4: 50 | BJ4: 50
A5: Topic Name | B5: Chemical Reactions and Equations | C5: Chemical Reactions and Equations | D5: Chemical Reactions and Equations | E5: Real Numbers | F5: Real Numbers | G5: Chemical Reactions and Equations | H5: Chemical Reactions and Equations | I5: Chemical Reactions and Equations | J5: Real Numbers | K5: Polynomials | L5: Chemical Reactions and Equations | M5: Chemical Reactions and Equations | N5: Chemical Reactions and Equations | O5: Chemical Reactions and Equations | P5: Chemical Reactions and Equations | Q5: Chemical Reactions and Equations | R5: Chemical Reactions and Equations | S5: Chemical Reactions and Equations | T5: Real Numbers | U5: Chemical Reactions and Equations | V5: Polynomials | W5: Polynomials | X5: Life Processes | Y5: Life Processes | Z5: Pair of Linear Equations in Two Variables | AA5: Pair of Linear Equations in Two Variables | AB5: Light – Reflection and Refraction | AC5: Light – Reflection and Refraction | AD5: Pair of Linear Equations in Two Variables | AE5: Light – Reflection and Refraction | AF5: Light – Reflection and Refraction | AG5: Light – Reflection and Refraction | AH5: Light – Reflection and Refraction | AI5: Pair of Linear Equations in Two Variables | AJ5: Polynomials | AK5: Pair of Linear Equations in Two Variables | AL5: Light – Reflection and Refraction | AM5: Pair of Linear Equations in Two Variables | AN5: Real Numbers | AO5: Light – Reflection and Refraction | AP5: Polynomials | AQ5: Light – Reflection and Refraction | AR5: Chemical Reactions and Equations | AS5: Life Processes | AT5: Life Processes | AU5: Life Processes | AV5: Pair of Linear Equations in Two Variables | AW5: Pair of Linear Equations in Two Variables | AX5: Life Processes | AY5: Pair of Linear Equations in Two Variables | AZ5: Life Processes | BA5: Life Processes | BB5: Chemical Reactions and Equations | BC5: Light – Reflection and Refraction | BD5: Pair of Linear Equations in Two Variables | BE5: Pair of Linear Equations in Two Variables | BF5: Polynomials | BG5: Real Numbers | BH5: Life Processes | BI5: Life Processes | BJ5: Pair of Linear Equations in Two Variables
A6: Aadit Jain | B6: 18 | C6: 48 | D6: 50 | E6: 39 | F6: 26 | G6: 36 | H6: 32 | I6: 48 | J6: 15 | K6: 26 | L6: 14 | M6: 20 | N6: 36 | O6: 34 | P6: 40 | Q6: 23 | R6: 38 | S6: 40 | T6: 27 | U6: 39 | V6: 33 | W6: 56 | X6: 26 | Y6: 32 | Z6: 21 | AA6: 45 | AB6: 28 | AC6: 34 | AD6: 48 | AE6: 42 | AF6: 39 | AG6: 49 | AH6: 38 | AI6: 29 | AJ6: 56 | AK6: 36 | AL6: 66 | AM6: 25 | AN6: 33 | AO6: 22 | AP6: 30 | AQ6: 58 | AR6: 68 | AS6: 42 | AT6: 32 | AU6: 39 | AV6: 40 | AW6: 44 | AX6: 54 | AY6: 42 | AZ6: 61 | BA6: 76 | BB6: 44 | BC6: 40 | BD6: 23 | BE6: 30 | BF6: 30 | BG6: 24 | BH6: 67 | BI6: 40 | BJ6: 37
A7: Aahaan Verma | B7: 12 | C7: 50 | D7: 48 | E7: 42 | F7: 22 | G7: 30 | H7: 34 | I7: 46 | J7: 10 | K7: 32 | L7: 10 | M7: 24 | N7: 38 | O7: 32 | P7: 36 | Q7: 25 | R7: 34 | S7: 36 | T7: 28 | U7: 40 | V7: 42 | W7: 42 | X7: 22 | Y7: 32 | Z7: 33 | AA7: 45 | AB7: 18 | AC7: 24 | AD7: 36 | AE7: 28 | AF7: 34 | AG7: 47 | AH7: 43 | AI7: 24 | AJ7: 49 | AK7: 33 | AL7: 67 | AM7: 24 | AN7: 34 | AO7: 27 | AP7: 30 | AQ7: 52 | AR7: 56 | AS7: 48 | AT7: Absent | AU7: 20 | AV7: 36 | AW7: 40 | AX7: 36 | AY7: 36 | AZ7: 41 | BA7: 64 | BB7: 38 | BC7: 40 | BD7: 27 | BE7: 30 | BF7: 26 | BG7: 26 | BH7: 53 | BI7: 20 | BJ7: 49
A8: Aakhya Verma | B8: 20 | C8: 44 | D8: Absent | E8: Absent | F8: 17 | G8: 32 | H8: 32 | I8: 42 | J8: 11 | K8: 30 | L8: 6 | M8: 34 | N8: 38 | O8: 40 | P8: 40 | Q8: 25 | R8: 40 | S8: 40 | T8: 30 | U8: Absent | V8: Absent | W8: 54 | X8: 32 | Y8: 34 | Z8: 42 | AA8: 45 | AB8: 28 | AC8: Absent | AD8: Absent | AE8: Absent | AF8: Absent | AG8: 23 | AH8: Absent | AI8: Absent | AJ8: Absent | AK8: 18 | AL8: 60 | AM8: Absent | AN8: Absent | AO8: 8 | AP8: Absent | AQ8: Absent | AR8: Absent | AS8: Absent | AT8: 38 | AU8: 46 | AV8: 33 | AW8: 27 | AX8: 54 | AY8: 42 | AZ8: 65 | BA8: Absent | BB8: Absent | BC8: Absent | BD8: 20 | BE8: Absent | BF8: Absent | BG8: Absent | BH8: Absent | BI8: 40 | BJ8: 16
A9: Aarav Dutta | B9: 14 | C9: Absent | D9: Absent | E9: Absent | F9: Absent | G9: Absent | H9: Absent | I9: Absent | J9: 9 | K9: 24 | L9: 8 | M9: 22 | N9: 30 | O9: Absent | P9: Absent | Q9: 7 | R9: 30 | S9: 16 | T9: 30 | U9: 36 | V9: 37 | W9: 56 | X9: 24 | Y9: 24 | Z9: 33 | AA9: 36 | AB9: 30 | AC9: 22 | AD9: 39 | AE9: Absent | AF9: 19 | AG9: 47 | AH9: 38 | AI9: 23 | AJ9: 64 | AK9: 33 | AL9: 69 | AM9: 22 | AN9: 26 | AO9: 11 | AP9: 29 | AQ9: 42 | AR9: 54 | AS9: 24 | AT9: 29 | AU9: 33 | AV9: Absent | AW9: 49 | AX9: 38 | AY9: 42 | AZ9: 43 | BA9: 66 | BB9: 30 | BC9: 34 | BD9: 19 | BE9: 22 | BF9: 30 | BG9: 30 | BH9: Absent | BI9: 30 | BJ9: Absent
A10: Aarish Aggarwal | B10: 20 | C10: 50 | D10: 50 | E10: 45 | F10: 26 | G10: 36 | H10: 36 | I10: 50 | J10: Absent | K10: 38 | L10: Absent | M10: 28 | N10: 40 | O10: 40 | P10: 40 | Q10: 25 | R10: 40 | S10: 40 | T10: 30 | U10: 45 | V10: 45 | W10: 65 | X10: 38 | Y10: 38 | Z10: 45 | AA10: 45 | AB10: 32 | AC10: 38 | AD10: 54 | AE10: 42 | AF10: 39 | AG10: 52 | AH10: 43 | AI10: 31 | AJ10: 70 | AK10: 39 | AL10: 75 | AM10: 21 | AN10: 40 | AO10: 30 | AP10: 29 | AQ10: 56 | AR10: 78 | AS10: 48 | AT10: 41 | AU10: 46 | AV10: 40 | AW10: 50 | AX10: 52 | AY10: 45 | AZ10: 66 | BA10: 76 | BB10: 44 | BC10: 42 | BD10: 26 | BE10: 28 | BF10: 28 | BG10: 30 | BH10: 70 | BI10: 50 | BJ10: 50
A11: Aarna Khurana | B11: 20 | C11: 45 | D11: 46 | E11: 45 | F11: 22 | G11: 36 | H11: 34 | I11: 44 | J11: 14 | K11: Absent | L11: 10 | M11: Absent | N11: 32 | O11: 34 | P11: 32 | Q11: 14 | R11: 28 | S11: 32 | T11: 28 | U11: 40 | V11: 42 | W11: 52 | X11: 34 | Y11: 34 | Z11: 36 | AA11: 45 | AB11: 30 | AC11: Absent | AD11: Absent | AE11: Absent | AF11: Absent | AG11: 41 | AH11: 43 | AI11: 27 | AJ11: 63 | AK11: 36 | AL11: 51 | AM11: Absent | AN11: Absent | AO11: 15 | AP11: Absent | AQ11: 48 | AR11: 60 | AS11: 44 | AT11: 41 | AU11: 46 | AV11: 39 | AW11: 49 | AX11: 42 | AY11: 45 | AZ11: 63 | BA11: 72 | BB11: 38 | BC11: 38 | BD11: 24 | BE11: 24 | BF11: 28 | BG11: 30 | BH11: 70 | BI11: 42 | BJ11: 45
A12: Aarush Sahi | B12: 18 | C12: 46 | D12: 48 | E12: 45 | F12: 25 | G12: 30 | H12: 30 | I12: 46 | J12: 15 | K12: 34 | L12: 11 | M12: 34 | N12: 32 | O12: Absent | P12: Absent | Q12: Absent | R12: 34 | S12: 40 | T12: 29 | U12: 39 | V12: 41 | W12: 58 | X12: 32 | Y12: 34 | Z12: 42 | AA12: 45 | AB12: 38 | AC12: 38 | AD12: 54 | AE12: 40 | AF12: 40 | AG12: 49 | AH12: 40 | AI12: 35 | AJ12: 58 | AK12: 39 | AL12: 73 | AM12: 25 | AN12: 34 | AO12: Absent | AP12: 30 | AQ12: Absent | AR12: Absent | AS12: Absent | AT12: 24 | AU12: 32 | AV12: Absent | AW12: 40 | AX12: 42 | AY12: 45 | AZ12: 59 | BA12: 74 | BB12: 42 | BC12: 40 | BD12: 21 | BE12: 26 | BF12: 30 | BG12: 28 | BH12: 70 | BI12: 34 | BJ12: 38
A13: Aaryaveer | B13: 16 | C13: 48 | D13: 50 | E13: 33 | F13: 26 | G13: 26 | H13: 24 | I13: 50 | J13: 12 | K13: 34 | L13: 15 | M13: 20 | N13: 32 | O13: 40 | P13: 36 | Q13: 25 | R13: 38 | S13: 40 | T13: 30 | U13: Absent | V13: Absent | W13: 56 | X13: 24 | Y13: 28 | Z13: 27 | AA13: 45 | AB13: 34 | AC13: 18 | AD13: 48 | AE13: 26 | AF13: 11 | AG13: 47 | AH13: 35 | AI13: 26 | AJ13: 66 | AK13: 39 | AL13: 75 | AM13: 16 | AN13: 35 | AO13: 21 | AP13: 29 | AQ13: 54 | AR13: 44 | AS13: 48 | AT13: 23 | AU13: 35 | AV13: 30 | AW13: 32 | AX13: 50 | AY13: 36 | AZ13: 56 | BA13: 74 | BB13: 42 | BC13: 42 | BD13: 26 | BE13: 24 | BF13: 30 | BG13: 24 | BH13: 65 | BI13: 38 | BJ13: 42
A14: Adhiraj Aggarwal | B14: Absent | C14: 50 | D14: 50 | E14: 45 | F14: 25 | G14: 36 | H14: 38 | I14: 50 | J14: Absent | K14: 34 | L14: Absent | M14: 38 | N14: Absent | O14: 32 | P14: 36 | Q14: 25 | R14: Absent | S14: 40 | T14: 30 | U14: 36 | V14: 45 | W14: 61 | X14: 32 | Y14: 38 | Z14: 39 | AA14: 45 | AB14: 34 | AC14: 36 | AD14: 51 | AE14: Absent | AF14: 23 | AG14: 51 | AH14: 48 | AI14: 30 | AJ14: 63 | AK14: Absent | AL14: Absent | AM14: 25 | AN14: 29 | AO14: Absent | AP14: 26 | AQ14: Absent | AR14: Absent | AS14: Absent | AT14: 35 | AU14: 37 | AV14: Absent | AW14: Absent | AX14: Absent | AY14: Absent | AZ14: Absent | BA14: 60 | BB14: 45 | BC14: 42 | BD14: Absent | BE14: 24 | BF14: 30 | BG14: 30 | BH14: Absent | BI14: 28 | BJ14: Absent
A15: Advik Kansal | B15: Absent | C15: 49 | D15: 50 | E15: 39 | F15: 22 | G15: 30 | H15: 36 | I15: 50 | J15: 15 | K15: 32 | L15: 14 | M15: 34 | N15: Absent | O15: 38 | P15: 38 | Q15: 18 | R15: 40 | S15: 40 | T15: Absent | U15: 45 | V15: 43 | W15: 65 | X15: 32 | Y15: 40 | Z15: 39 | AA15: 45 | AB15: 34 | AC15: 34 | AD15: 48 | AE15: 42 | AF15: 39 | AG15: 53 | AH15: 43 | AI15: 32 | AJ15: 70 | AK15: 39 | AL15: 70 | AN15: 36 | AO15: 30 | AP15: 30 | AQ15: 54 | AR15: 62 | AS15: 40 | AT15: 42 | AU15: 40 | AV15: Absent | AW15: Absent | AX15: 54 | AY15: 45 | AZ15: 70 | BA15: 80 | BB15: 45 | BC15: 42 | BD15: 20 | BE15: 26 | BF15: 30 | BG15: 26 | BH15: 70 | BI15: 44 | BJ15: 46
A16: Advika Garg | B16: 20 | C16: 41 | D16: 42 | E16: 39 | F16: 29 | G16: 34 | H16: 34 | I16: 44 | J16: 15 | K16: 30 | L16: 9 | M16: 36 | N16: Absent | O16: 38 | P16: 38 | Q16: 24 | R16: 36 | S16: 39 | T16: 30 | U16: 45 | V16: 40 | W16: 49 | X16: 38 | Y16: 40 | Z16: 42 | AA16: 45 | AB16: 32 | AC16: 38 | AD16: 45 | AE16: 42 | AF16: 38 | AG16: Absent | AH16: Absent | AI16: Absent | AJ16: Absent | AK16: Absent | AL16: Absent | AM16: 25 | AN16: 29 | AO16: Absent | AP16: 17 | AQ16: 44 | AR16: 74 | AS16: 48 | AT16: 45 | AU16: 50 | AV16: 31 | AW16: 45 | AX16: 52 | AY16: 39 | AZ16: 66 | BA16: 76 | BB16: 45 | BC16: 42 | BD16: 30 | BE16: 18 | BF16: 30 | BG16: 28 | BH16: 70 | BI16: 44 | BJ16: 27
A17: Akshita Garg | B17: 18 | C17: 50 | D17: 48 | E17: 36 | F17: 27 | G17: 32 | H17: 34 | I17: 46 | J17: 12 | K17: 38 | L17: 10 | M17: 32 | N17: Absent | O17: 38 | P17: 30 | Q17: 16 | R17: 40 | S17: 32 | T17: 28 | U17: 40 | V17: 43 | W17: 61 | X17: 30 | Y17: 34 | Z17: 39 | AA17: 45 | AB17: 32 | AC17: 38 | AD17: 51 | AE17: Absent | AF17: 32 | AG17: 49 | AH17: 48 | AI17: 26 | AJ17: 61 | AK17: 33 | AL17: 69 | AM17: Absent | AN17: 35 | AO17: 26 | AP17: 28 | AQ17: 56 | AR17: 74 | AS17: 42 | AT17: 30 | AU17: 36 | AV17: Absent | AW17: 41 | AX17: 50 | AY17: 42 | AZ17: 63 | BA17: 72 | BB17: 38 | BC17: 40 | BD17: 30 | BE17: 26 | BF17: 30 | BG17: 26 | BH17: Absent | BI17: Absent | BJ17: Absent
A18: Amyra Arora | B18: 20 | C18: 50 | D18: 49 | E18: 42 | F18: 22 | G18: 38 | H18: 38 | I18: 46 | J18: 15 | K18: 26 | L18: 14 | M18: 28 | N18: 40 | O18: 38 | P18: 36 | Q18: 25 | R18: 40 | S18: 40 | T18: 30 | U18: 45 | V18: 45 | W18: 56 | X18: 36 | Y18: 36 | Z18: 39 | AA18: 39 | AB18: 28 | AC18: Absent | AD18: Absent | AE18: Absent | AF18: Absent | AG18: 47 | AH18: 43 | AI18: 26 | AJ18: 66 | AK18: Absent | AL18: Absent | AM18: Absent | AN18: Absent | AO18: 26 | AP18: Absent | AQ18: 56 | AR18: 76 | AS18: 48 | AT18: 41 | AU18: 43 | AV18: 31 | AW18: 45 | AX18: 55 | AY18: 45 | AZ18: 70 | BA18: 78 | BB18: 40 | BC18: 42 | BD18: 25 | BE18: 30 | BF18: 28 | BG18: 28 | BH18: 70 | BI18: 46 | BJ18: 44
A19: Arhat Jain | B19: 20 | C19: 50 | D19: 50 | E19: 39 | F19: 26 | G19: 36 | H19: 38 | I19: 48 | J19: 15 | K19: 34 | L19: 15 | M19: 32 | N19: 40 | O19: 40 | P19: 36 | Q19: 25 | R19: 40 | S19: 40 | T19: 30 | U19: 45 | V19: 45 | W19: 65 | X19: 38 | Y19: 40 | Z19: 39 | AA19: 45 | AB19: 30 | AC19: 38 | AD19: 45 | AE19: 42 | AF19: 40 | AG19: 51 | AH19: 48 | AI19: 32 | AJ19: 70 | AK19: 39 | AL19: 72 | AM19: 25 | AN19: 34 | AO19: 30 | AP19: 30 | AQ19: 58 | AR19: 70 | AS19: 36 | AT19: 44 | AU19: 44 | AV19: 40 | AW19: 50 | AX19: Absent | AY19: Absent | AZ19: 70 | BA19: 74 | BB19: 42 | BC19: 42 | BD19: 30 | BE19: 30 | BF19: 28 | BG19: 30 | BH19: 70 | BI19: Absent | BJ19: Absent
A20: Arshia Singh | B20: 18 | C20: 34 | D20: 32 | E20: 42 | F20: 21 | G20: Absent | H20: 28 | I20: 24 | J20: 12 | K20: 36 | L20: 15 | M20: 32 | N20: 34 | O20: 34 | P20: 28 | Q20: 19 | R20: 34 | S20: 27 | T20: 25 | U20: 40 | V20: 41 | W20: 51 | X20: 26 | Y20: 30 | Z20: 42 | AA20: 42 | AB20: 34 | AC20: Absent | AD20: Absent | AE20: Absent | AF20: Absent | AG20: Absent | AH20: 23 | AI20: 23 | AJ20: 54 | AK20: 33 | AL20: 59 | AM20: Absent | AN20: 28 | AO20: 21 | AP20: 16 | AQ20: Absent | AR20: Absent | AS20: Absent | AT20: 33 | AU20: 36 | AV20: 28 | AW20: 37 | AX20: 50 | AY20: 39 | AZ20: 61 | BA20: 62 | BB20: 36 | BC20: 38 | BD20: 26 | BE20: 26 | BF20: 30 | BG20: 26 | BH20: Absent | BI20: 46 | BJ20: 32
A21: Bhavya Talwar | B21: 18 | C21: 49 | D21: 49 | E21: 42 | F21: 18 | G21: 34 | H21: 32 | I21: 50 | J21: 15 | K21: 32 | L21: 13 | M21: 34 | N21: 36 | O21: 36 | P21: 36 | Q21: 23 | R21: 38 | S21: 40 | T21: 27 | U21: 45 | V21: 43 | W21: 65 | X21: 36 | Y21: 38 | Z21: 39 | AA21: Absent | AB21: Absent | AC21: Absent | AD21: Absent | AE21: 32 | AF21: Absent | AG21: 51 | AH21: 45 | AI21: 26 | AJ21: 68 | AK21: 33 | AL21: 73 | AM21: 20 | AN21: Absent | AO21: 24 | AP21: Absent | AQ21: Absent | AR21: Absent | AS21: Absent | AT21: 36 | AU21: 42 | AV21: 39 | AW21: Absent | AX21: 50 | AY21: 42 | AZ21: 58 | BA21: 74 | BB21: 40 | BC21: 42 | BD21: 17 | BE21: 26 | BF21: 30 | BG21: 28 | BH21: 68 | BI21: 44 | BJ21: 31
A22: Daksh Devgan | B22: 16 | C22: 48 | D22: 44 | E22: 42 | F22: Absent | G22: Absent | H22: 36 | I22: 46 | J22: 7 | K22: 30 | L22: 5 | M22: 22 | N22: Absent | O22: 28 | P22: 22 | Q22: 22 | R22: 30 | S22: 29 | T22: 27 | U22: 30 | V22: 42 | W22: 59 | X22: 30 | Y22: 28 | Z22: 36 | AA22: 45 | AB22: 36 | AC22: 32 | AD22: 45 | AE22: 28 | AF22: 39 | AG22: 53 | AH22: 40 | AI22: 31 | AJ22: 56 | AK22: 24 | AL22: 69 | AM22: 20 | AN22: 22 | AO22: 18 | AP22: 17 | AQ22: 52 | AR22: 70 | AS22: 48 | AT22: 38 | AU22: Absent | AV22: Absent | AW22: 39 | AX22: 42 | AY22: 36 | AZ22: 54 | BA22: Absent | BB22: Absent | BC22: Absent | BD22: 19 | BE22: Absent | BF22: Absent | BG22: Absent | BH22: Absent | BI22: Absent | BJ22: 26
A23: Daksh Gupta | B23: 20 | C23: 50 | D23: 50 | E23: 45 | F23: 26 | G23: 28 | H23: 30 | I23: 50 | J23: 12 | K23: 36 | L23: 12 | M23: 26 | N23: 40 | O23: 38 | P23: 36 | Q23: 25 | R23: 36 | S23: 40 | T23: 24 | U23: 45 | V23: 43 | W23: 61 | X23: 34 | Y23: 34 | Z23: 42 | AA23: 45 | AB23: 34 | AC23: 38 | AD23: 54 | AE23: 44 | AF23: 32 | AG23: 51 | AH23: 48 | AI23: 25 | AJ23: 63 | AK23: 33 | AL23: 68 | AM23: 25 | AN23: 38 | AO23: 25 | AP23: 30 | AQ23: 58 | AR23: 76 | AS23: 44 | AT23: 37 | AU23: 40 | AV23: 40 | AW23: 46 | AX23: 50 | AY23: 42 | AZ23: 64 | BA23: 74 | BB23: 44 | BC23: 42 | BD23: 28 | BE23: 26 | BF23: 30 | BG23: 30 | BH23: 66 | BI23: 46 | BJ23: 50
A24: Divyanshi Chopra | B24: 18 | C24: Absent | D24: 46 | E24: 42 | F24: 27 | G24: 38 | H24: 38 | I24: 49 | J24: 15 | K24: 40 | L24: 15 | M24: 38 | N24: 40 | O24: 40 | P24: 34 | Q24: 23 | R24: 38 | S24: 40 | T24: Absent | U24: 45 | V24: 43 | W24: 65 | X24: 30 | Y24: 36 | Z24: 42 | AA24: 45 | AB24: 38 | AC24: 38 | AD24: 48 | AE24: 45 | AF24: 40 | AG24: 53 | AH24: 48 | AI24: 35 | AJ24: 70 | AK24: Absent | AL24: Absent | AM24: 25 | AN24: 40 | AO24: 28 | AP24: 30 | AQ24: 58 | AR24: 76 | AS24: 42 | AT24: 45 | AU24: 50 | AV24: Absent | AW24: 49 | AX24: Absent | AY24: Absent | AZ24: 70 | BA24: 80 | BB24: 45 | BC24: 42 | BD24: 30 | BE24: 28 | BF24: 30 | BG24: 28 | BH24: 70 | BI24: Absent | BJ24: 49
A25: Diya Dang | B25: 14 | C25: 48 | D25: 46 | E25: 36 | F25: 25 | G25: 28 | H25: 30 | I25: 50 | J25: 8 | K25: 32 | L25: 10 | M25: 26 | N25: Absent | O25: Absent | P25: Absent | Q25: Absent | R25: 24 | S25: 30 | T25: 24 | U25: 27 | V25: 39 | W25: 46 | X25: 34 | Y25: Absent | Z25: 27 | AA25: Absent | AB25: Absent | AC25: 24 | AD25: 51 | AE25: 32 | AF25: 27 | AG25: 51 | AH25: Absent | AI25: Absent | AJ25: Absent | AK25: 24 | AL25: 65 | AM25: 16 | AN25: Absent | AO25: Absent | AP25: Absent | AQ25: Absent | AR25: Absent | AS25: Absent | AT25: Absent | AU25: 29 | AV25: 16 | AW25: Absent | AX25: Absent | AY25: Absent | AZ25: 30 | BA25: 72 | BB25: 36 | BC25: 38 | BD25: 7 | BE25: 20 | BF25: 22 | BG25: 26 | BH25: 60 | BI25: 32 | BJ25: Absent
A26: Gyanda Sinha | B26: 20 | C26: 32 | D26: 41 | E26: 24 | F26: 24 | G26: 38 | H26: 38 | I26: 33 | J26: 15 | K26: Absent | L26: 14 | M26: Absent | N26: 34 | O26: 36 | P26: 34 | Q26: 20 | R26: 34 | S26: 40 | T26: 30 | U26: 36 | V26: 38 | W26: Absent | X26: Absent | Y26: Absent | Z26: Absent | AA26: Absent | AB26: Absent | AC26: 28 | AD26: 24 | AE26: 28 | AF26: 30 | AG26: 49 | AH26: 38 | AI26: 14 | AJ26: 37 | AK26: 30 | AL26: 59 | AM26: 6 | AN26: 28 | AO26: 23 | AP26: 21 | AQ26: 44 | AR26: 70 | AS26: 46 | AT26: 45 | AU26: 46 | AV26: 16 | AW26: 23 | AX26: 50 | AY26: 36 | AZ26: 70 | BA26: Absent | BB26: Absent | BC26: Absent | BD26: 13 | BE26: Absent | BF26: Absent | BG26: Absent | BH26: Absent | BI26: 42 | BJ26: 18
A27: Harseerat Sandhu | B27: Absent | C27: 40 | D27: 43 | E27: 24 | F27: 23 | G27: Absent | H27: 22 | I27: 38 | J27: 10 | K27: Absent | L27: 6 | M27: Absent | N27: 26 | O27: 36 | P27: 36 | Q27: 20 | R27: 36 | S27: 31 | T27: 25 | U27: 38 | V27: 29 | W27: 37 | X27: 32 | Y27: 36 | Z27: Absent | AA27: Absent | AB27: 30 | AC27: 16 | AD27: Absent | AE27: Absent | AF27: 11 | AG27: 32 | AH27: 23 | AI27: 14 | AJ27: 35 | AK27: 21 | AL27: 52 | AM27: Absent | AN27: Absent | AO27: Absent | AP27: Absent | AQ27: 38 | AR27: 70 | AS27: 44 | AT27: Absent | AU27: 21 | AV27: Absent | AW27: 9 | AX27: 36 | AY27: 21 | AZ27: Absent | BA27: Absent | BB27: Absent | BC27: Absent | BD27: Absent | BE27: Absent | BF27: Absent | BG27: Absent | BH27: Absent | BI27: Absent | BJ27: Absent
A28: Hridaan Verma | B28: 22 | C28: 23 | D28: 34 | E28: 30 | F28: 19 | G28: 36 | H28: 34 | I28: 34 | J28: 11 | K28: 28 | L28: 13 | M28: 30 | N28: 38 | O28: 36 | P28: 38 | Q28: 25 | R28: 36 | S28: 31 | T28: 29 | U28: 38 | V28: 33 | W28: 47 | X28: 34 | Y28: 38 | Z28: 27 | AA28: Absent | AB28: Absent | AC28: 30 | AD28: 36 | AE28: 45 | AF28: 17 | AG28: 53 | AH28: Absent | AI28: Absent | AJ28: Absent | AK28: 24 | AL28: 69 | AM28: 17 | AN28: 32 | AO28: 27 | AP28: 18 | AQ28: 38 | AR28: 78 | AS28: 46 | AT28: 36 | AU28: 38 | AV28: 17 | AW28: 41 | AX28: 55 | AY28: 36 | AZ28: Absent | BA28: Absent | BB28: Absent | BC28: Absent | BD28: Absent | BE28: Absent | BF28: Absent | BG28: Absent | BH28: Absent | BI28: Absent | BJ28: Absent
A29: Hrishita | B29: 18 | C29: 50 | D29: 50 | E29: 42 | F29: 25 | G29: 36 | H29: 30 | I29: 47 | J29: 10 | K29: 32 | L29: 8 | M29: 16 | N29: 26 | O29: 34 | P29: 30 | Q29: 22 | R29: 34 | S29: 21 | T29: 19 | U29: Absent | V29: Absent | W29: 46 | X29: 30 | Y29: 30 | Z29: 39 | AA29: 42 | AB29: 20 | AC29: Absent | AD29: Absent | AE29: Absent | AF29: Absent | AG29: 23 | AH29: 20 | AI29: 28 | AJ29: 43 | AK29: 30 | AL29: 30 | AM29: Absent | AN29: 20 | AO29: 12 | AP29: 6 | AQ29: 34 | AR29: 56 | AS29: 42 | AT29: 38 | AU29: 45 | AV29: 21 | AW29: 20 | AX29: 46 | AY29: 36 | AZ29: 60 | BA29: 70 | BB29: 34 | BC29: 26 | BD29: 8 | BE29: 24 | BF29: 28 | BG29: 28 | BH29: 67 | BI29: 42 | BJ29: 23
A30: Jasnoor Singh | B30: 16 | C30: Absent | D30: 20 | E30: 39 | F30: 19 | G30: 32 | H30: Absent | I30: Absent | J30: 5 | K30: 28 | L30: 4 | M30: 22 | N30: Absent | O30: 28 | P30: 28 | Q30: 4 | R30: 32 | S30: 16 | T30: 17 | U30: 18 | V30: 41 | W30: 53 | X30: 22 | Y30: Absent | Z30: 18 | AA30: 45 | AB30: 28 | AC30: Absent | AD30: Absent | AE30: 34 | AF30: Absent | AG30: Absent | AH30: Absent | AI30: Absent | AJ30: Absent | AK30: Absent | AL30: Absent | AM30: 18 | AN30: 27 | AO30: Absent | AP30: 13 | AQ30: Absent | AR30: Absent | AS30: Absent | AT30: 29 | AU30: 35 | AV30: Absent | AW30: 15 | AX30: 48 | AY30: 36 | AZ30: 60 | BA30: Absent | BB30: Absent | BC30: Absent | BD30: 14 | BE30: Absent | BF30: Absent | BG30: Absent | BH30: 63 | BI30: Absent | BJ30: 16
A31: Kanhav Kochhar | B31: 18 | C31: Absent | D31: 50 | E31: 42 | F31: 20 | G31: 38 | H31: 36 | I31: 49 | J31: 8 | K31: 30 | L31: 10 | M31: 34 | N31: 30 | O31: 34 | P31: 36 | Q31: 24 | R31: 38 | S31: Absent | T31: 25 | U31: 43 | V31: 43 | W31: Absent | X31: Absent | Y31: Absent | Z31: Absent | AA31: Absent | AB31: Absent | AC31: 32 | AD31: Absent | AE31: 44 | AF31: 37 | AG31: 49 | AH31: 30 | AI31: 32 | AJ31: 65 | AK31: 33 | AL31: 65 | AM31: 22 | AN31: 25 | AO31: Absent | AP31: 25 | AQ31: 54 | AR31: 66 | AS31: 38 | AT31: 36 | AU31: Absent | AV31: Absent | AW31: Absent | AX31: 44 | AY31: 33 | AZ31: 48 | BA31: 68 | BB31: 42 | BC31: 42 | BD31: 22 | BE31: 24 | BF31: 28 | BG31: 30 | BH31: 59 | BI31: 44 | BJ31: 25
A32: Karanveer Singh Gill | B32: 20 | C32: Absent | D32: 46 | E32: 45 | F32: 23 | G32: 34 | H32: Absent | I32: Absent | J32: 12 | K32: 36 | L32: 11 | M32: 28 | N32: 32 | O32: Absent | P32: Absent | Q32: Absent | R32: Absent | S32: 34 | T32: 25 | U32: Absent | V32: Absent | W32: 65 | X32: 30 | Y32: 34 | Z32: 36 | AA32: 45 | AB32: 34 | AC32: 32 | AD32: 48 | AE32: 45 | AF32: 30 | AG32: 53 | AH32: 48 | AI32: 23 | AJ32: 58 | AK32: 39 | AL32: 69 | AM32: 21 | AN32: 29 | AO32: 23 | AP32: 22 | AQ32: 56 | AR32: 62 | AS32: 44 | AT32: 41 | AU32: 45 | AV32: 34 | AW32: 42 | AX32: 50 | AY32: 45 | AZ32: Absent | BA32: 76 | BB32: 38 | BC32: 40 | BD32: Absent | BE32: 28 | BF32: 30 | BG32: 30 | BH32: 66 | BI32: 42 | BJ32: 36
A33: Khushi | B33: Absent | C33: Absent | D33: 43 | E33: 45 | F33: 22 | G33: 28 | H33: 34 | I33: 41 | J33: 8 | K33: 30 | L33: 14 | M33: 28 | N33: 38 | O33: 34 | P33: 28 | Q33: 25 | R33: 32 | S33: 40 | T33: 21 | U33: 43 | V33: 34 | W33: 54 | X33: 26 | Y33: 34 | Z33: 30 | AA33: 36 | AB33: 24 | AC33: 36 | AD33: Absent | AE33: 32 | AF33: 39 | AG33: Absent | AH33: 43 | AI33: 21 | AJ33: 52 | AK33: 21 | AL33: 56 | AM33: 11 | AN33: 31 | AO33: 25 | AP33: 30 | AQ33: 54 | AR33: 60 | AS33: 44 | AT33: 39 | AU33: 42 | AV33: 20 | AW33: 30 | AX33: 26 | AY33: 39 | AZ33: 59 | BA33: 72 | BB33: 40 | BC33: 40 | BD33: 18 | BE33: 18 | BF33: 28 | BG33: 30 | BH33: 70 | BI33: 40 | BJ33: 31
A34: Madhav Manan | B34: Absent | C34: Absent | D34: Absent | E34: Absent | F34: Absent | G34: Absent | H34: Absent | I34: Absent | J34: Absent | K34: Absent | L34: Absent | M34: Absent | N34: Absent | O34: Absent | P34: Absent | Q34: Absent | R34: Absent | S34: Absent | T34: Absent | U34: Absent | V34: Absent | W34: Absent | X34: Absent | Y34: Absent | Z34: Absent | AA34: Absent | AB34: 16 | AC34: 16 | AD34: Absent | AE34: Absent | AF34: Absent | AG34: 43 | AH34: Absent | AI34: Absent | AJ34: Absent | AK34: 30 | AL34: Absent | AM34: Absent | AN34: Absent | AO34: 18 | AP34: Absent | AQ34: 56 | AR34: Absent | AS34: 30 | AT34: 24 | AU34: Absent | AV34: Absent | AW34: Absent | AX34: Absent | AY34: Absent | AZ34: Absent | BA34: Absent | BB34: Absent | BC34: Absent | BD34: Absent | BE34: Absent | BF34: Absent | BG34: Absent | BH34: Absent | BI34: Absent | BJ34: 11
A35: Meher Judge | B35: 18 | C35: 37 | D35: 37 | E35: 42 | F35: 19 | G35: Absent | H35: 34 | I35: 32 | J35: 9 | K35: 38 | L35: 12 | M35: 34 | N35: 34 | O35: Absent | P35: 38 | Q35: 18 | R35: Absent | S35: 39 | T35: 25 | U35: Absent | V35: 42 | W35: 65 | X35: 38 | Y35: Absent | Z35: 39 | AA35: 39 | AB35: 38 | AC35: 38 | AD35: 51 | AE35: 42 | AF35: 13 | AG35: 41 | AH35: 38 | AI35: 35 | AJ35: 61 | AK35: 36 | AL35: 50 | AM35: Absent | AN35: 14 | AO35: 15 | AP35: 10 | AQ35: 54 | AR35: 76 | AS35: 48 | AT35: 18 | AU35: Absent | AV35: Absent | AW35: 25 | AX35: Absent | AY35: Absent | AZ35: Absent | BA35: 68 | BB35: 44 | BC35: 42 | BD35: Absent | BE35: 30 | BF35: 20 | BG35: 30 | BH35: 70 | BI35: 46 | BJ35: 24
A36: Namya Gogia | B36: 14 | C36: 36 | D36: Absent | E36: Absent | F36: 21 | G36: 26 | H36: 26 | I36: 22 | J36: 7 | K36: 26 | L36: 3 | M36: 16 | N36: 20 | O36: 16 | P36: 20 | Q36: Absent | R36: 26 | S36: 16 | T36: 26 | U36: Absent | V36: Absent | W36: 12 | X36: 20 | Y36: Absent | Z36: 21 | AA36: 21 | AB36: 26 | AC36: 16 | AD36: 22 | AE36: 18 | AF36: 11 | AG36: 37 | AH36: 25 | AI36: 19 | AJ36: 28 | AK36: 16 | AL36: 51 | AM36: 12 | AN36: 13 | AO36: 14 | AP36: 2 | AQ36: 40 | AR36: 50 | AS36: 38 | AT36: 24 | AU36: 38 | AV36: Absent | AW36: 14 | AX36: 38 | AY36: 27 | AZ36: 57 | BA36: 68 | BB36: 24 | BC36: 26 | BD36: 18 | BE36: 22 | BF36: 22 | BG36: 28 | BH36: 53 | BI36: Absent | BJ36: Absent
A37: Navika Kohli | B37: 18 | C37: 48 | D37: 31 | E37: 27 | F37: 17 | G37: Absent | H37: 34 | I37: 39 | J37: 10 | K37: 36 | L37: 11 | M37: 26 | N37: 32 | O37: 38 | P37: 36 | Q37: 19 | R37: 36 | S37: 39 | T37: 18 | U37: Absent | V37: Absent | W37: 56 | X37: 34 | Y37: 34 | Z37: 36 | AA37: 45 | AB37: 26 | AC37: 32 | AD37: 39 | AE37: 38 | AF37: 40 | AG37: 49 | AH37: 38 | AI37: 19 | AJ37: 51 | AK37: 27 | AL37: 70 | AM37: 19 | AN37: 30 | AO37: 25 | AP37: 19 | AQ37: Absent | AR37: Absent | AS37: Absent | AT37: 41 | AU37: 45 | AV37: 22 | AW37: 39 | AX37: 50 | AY37: 39 | AZ37: 68 | BA37: 74 | BB37: 40 | BC37: 42 | BD37: 13 | BE37: 22 | BF37: 30 | BG37: 26 | BH37: Absent | BI37: 40 | BJ37: 30
A38: Nishchay Jain | B38: 18 | C38: 48 | D38: 39 | E38: 45 | F38: 17 | G38: Absent | H38: 28 | I38: 47 | J38: 11 | K38: 26 | L38: 7 | M38: 22 | N38: 30 | O38: 34 | P38: 36 | Q38: 17 | R38: 36 | S38: 23 | T38: 26 | U38: 37 | V38: 37 | W38: 51 | X38: 24 | Y38: 28 | Z38: 36 | AA38: 45 | AB38: 32 | AC38: 34 | AD38: 45 | AE38: 42 | AF38: 26 | AG38: 47 | AH38: 40 | AI38: 29 | AJ38: 65 | AK38: 27 | AL38: 68 | AM38: 23 | AN38: 30 | AO38: 6 | AP38: 22 | AQ38: 46 | AR38: 64 | AS38: 38 | AT38: 26 | AU38: 41 | AV38: 22 | AW38: 30 | AX38: 42 | AY38: 33 | AZ38: 56 | BA38: 70 | BB38: 42 | BC38: 34 | BD38: 20 | BE38: 22 | BF38: 28 | BG38: 28 | BH38: 68 | BI38: Absent | BJ38: Absent
A39: Nitya S Verma | B39: 20 | C39: 29 | D39: 44 | E39: 45 | F39: 22 | G39: 36 | H39: 30 | I39: 38 | J39: 15 | K39: 32 | L39: 14 | M39: 26 | N39: 38 | O39: 36 | P39: 32 | Q39: 22 | R39: 36 | S39: 40 | T39: 26 | U39: 41 | V39: 41 | W39: 59 | X39: 32 | Y39: 38 | Z39: 36 | AA39: 42 | AB39: 32 | AC39: 36 | AD39: 45 | AE39: 45 | AF39: 39 | AG39: 53 | AH39: 48 | AI39: 35 | AJ39: 56 | AK39: 36 | AL39: 75 | AM39: 20 | AN39: 34 | AO39: 23 | AP39: 29 | AQ39: 54 | AR39: 70 | AS39: 46 | AT39: 45 | AU39: 45 | AV39: 33 | AW39: Absent | AX39: 52 | AY39: 45 | AZ39: 70 | BA39: 76 | BB39: 44 | BC39: 42 | BD39: 16 | BE39: 26 | BF39: 28 | BG39: 30 | BH39: 70 | BI39: 48 | BJ39: 43
A40: Pranav Verma | B40: 20 | C40: 48 | D40: 44 | E40: 36 | F40: 29 | G40: Absent | H40: 32 | I40: 48 | J40: 15 | K40: 32 | L40: 12 | M40: 24 | N40: 36 | O40: 36 | P40: 36 | Q40: 25 | R40: 38 | S40: 40 | T40: 25 | U40: 45 | V40: 40 | W40: 49 | X40: 28 | Y40: 34 | Z40: 36 | AA40: 45 | AB40: 32 | AC40: 26 | AD40: 22 | AE40: 38 | AF40: Absent | AG40: Absent | AH40: 23 | AI40: 32 | AJ40: 66 | AK40: 33 | AL40: 60 | AM40: 20 | AN40: 36 | AO40: Absent | AP40: 30 | AQ40: 48 | AR40: 72 | AS40: 46 | AT40: 42 | AU40: 39 | AV40: 23 | AW40: 48 | AX40: 50 | AY40: 42 | AZ40: 44 | BA40: 74 | BB40: 42 | BC40: 36 | BD40: 29 | BE40: 12 | BF40: 12 | BG40: 12 | BH40: Absent | BI40: 34 | BJ40: 40
...

Sheet Chapters
A1: Chapters
A2: Real Numbers
A3: Polynomials
A4: Pair of Linear Equations in Two Variables
A5: Quadratic Equation
A6: Arithmetic Progression
A7: Triangles
A8: Coordinate Geometry
A9: Introduction to Trigonometry
A10: Some Applications of Trigonometry
A11: Circles
A12: Areas Related to Circles
... A31: Science Diagram

Sheet Whatsapp Scores Notification Sh
C1: 📊 Dashboard | D1: Whatsapp Send Button
C2: Dashboard Link | D2: =RawData!A2 -> Date | E2: =RawData!B2 -> 46118 | F2: =RawData!C2 -> 46119 | G2: =RawData!D2 -> 46120 | H2: =RawData!E2 -> 46120 | I2: =RawData!F2 -> 46121 | J2: =RawData!G2 -> 46122 | K2: =RawData!H2 -> 46126 | ... LK2: =RawData!LH2
C3: Student Dashboard | D3: =RawData!A3 -> Subject | E3: =RawData!B3 -> Science | F3: =RawData!C3 -> Science | G3: =RawData!D3 -> Science | H3: =RawData!E3 -> Maths | I3: =RawData!F3 -> Maths | J3: =RawData!G3 -> Science | K3: =RawData!H3 -> Science | ... LK3: =RawData!LH3
C4: Looker Studio | D4: =RawData!A4 -> Total Marks | E4: =RawData!B4 -> 20 | F4: =RawData!C4 -> 50 | G4: =RawData!D4 -> 50 | H4: =RawData!E4 -> 45 | I4: =RawData!F4 -> 30 | J4: =RawData!G4 -> 40 | K4: =RawData!H4 -> 38 | ... LK4: =RawData!LH4
A5: Parent Name | B5: Phone Number | C5: Dashboard Link | D5: =RawData!A5 -> Topic Name | E5: =RawData!B5 -> Chemical Reactions and Equations | F5: =RawData!C5 -> Chemical Reactions and Equations | G5: =RawData!D5 -> Chemical Reactions and Equations | H5: =RawData!E5 -> Real Numbers | I5: =RawData!F5 -> Real Numbers | J5: =RawData!G5 -> Chemical Reactions and Equations | K5: =RawData!H5 -> Chemical Reactions and Equations | ... LK5: =RawData!LH5
A6: Mrs. Isha Jain | B6: 9802080000 | C6: https://lookerstudio.google.com/reporting/1d4419ee-1be6-46ab-a94d-51a23019b02b | D6: =INDIRECT("RawData!"&ADDRESS(ROW(),1)) -> Aadit Jain | E6: =INDIRECT("RawData!"&ADDRESS(ROW(),COLUMN()-3)) -> 18 | F6: =INDIRECT("RawData!"&ADDRESS(ROW(),COLUMN()-3)) -> 48 | G6: =INDIRECT("RawData!"&ADDRESS(ROW(),COLUMN()-3)) -> 50 | H6: =INDIRECT("RawData!"&ADDRESS(ROW(),COLUMN()-3)) -> 39 | I6: =INDIRECT("RawData!"&ADDRESS(ROW(),COLUMN()-3)) -> 26 | J6: =INDIRECT("RawData!"&ADDRESS(ROW(),COLUMN()-3)) -> 36 | K6: =INDIRECT("RawData!"&ADDRESS(ROW(),COLUMN()-3)) -> 32 | L6: =INDIRECT("RawData!"&ADDRESS(ROW(),COLUMN()-3)) -> 48 | ... LK6: =INDIRECT("RawData!"&ADDRESS(ROW(),COLUMN()-3))
A7: Mr. Shashank Verma | B7: 9416204259 | C7: https://lookerstudio.google.com/reporting/837c8441-222f-4199-8bde-5064633a41de | D7: =INDIRECT("RawData!"&ADDRESS(ROW(),1)) -> Aahaan Verma | E7: =INDIRECT("RawData!"&ADDRESS(ROW(),COLUMN()-3)) -> 12 | F7: =INDIRECT("RawData!"&ADDRESS(ROW(),COLUMN()-3)) -> 50 | G7: =INDIRECT("RawData!"&ADDRESS(ROW(),COLUMN()-3)) -> 48 | H7: =INDIRECT("RawData!"&ADDRESS(ROW(),COLUMN()-3)) -> 42 | I7: =INDIRECT("RawData!"&ADDRESS(ROW(),COLUMN()-3)) -> 22 | J7: =INDIRECT("RawData!"&ADDRESS(ROW(),COLUMN()-3)) -> 30 | K7: =INDIRECT("RawData!"&ADDRESS(ROW(),COLUMN()-3)) -> 34 | L7: =INDIRECT("RawData!"&ADDRESS(ROW(),COLUMN()-3)) -> 46 | ... LK7: =INDIRECT("RawData!"&ADDRESS(ROW(),COLUMN()-3))
A8: Mrs. Neetu Verma | B8: 9813557570 | C8: https://lookerstudio.google.com/reporting/f1faf766-7e0c-4d87-8056-42e5b6b82bda | D8: =INDIRECT("RawData!"&ADDRESS(ROW(),1)) -> Aakhya Verma | E8: =INDIRECT("RawData!"&ADDRESS(ROW(),COLUMN()-3)) -> 20 | F8: =INDIRECT("RawData!"&ADDRESS(ROW(),COLUMN()-3)) -> 44 | G8: =INDIRECT("RawData!"&ADDRESS(ROW(),COLUMN()-3)) -> Absent | H8: =INDIRECT("RawData!"&ADDRESS(ROW(),COLUMN()-3)) -> Absent | I8: =INDIRECT("RawData!"&ADDRESS(ROW(),COLUMN()-3)) -> 17 | J8: =INDIRECT("RawData!"&ADDRESS(ROW(),COLUMN()-3)) -> 32 | K8: =INDIRECT("RawData!"&ADDRESS(ROW(),COLUMN()-3)) -> 32 | L8: =INDIRECT("RawData!"&ADDRESS(ROW(),COLUMN()-3)) -> 42 | ... LK8: =INDIRECT("RawData!"&ADDRESS(ROW(),COLUMN()-3))
A9: Mrs. Shasita | B9: 8168736926 | C9: https://datastudio.google.com/reporting/64859623-f473-443c-a144-c4c23c0f4b59 | D9: =INDIRECT("RawData!"&ADDRESS(ROW(),1)) -> Aarav Dutta | E9: =INDIRECT("RawData!"&ADDRESS(ROW(),COLUMN()-3)) -> 14 | F9: =INDIRECT("RawData!"&ADDRESS(ROW(),COLUMN()-3)) -> Absent | G9: =INDIRECT("RawData!"&ADDRESS(ROW(),COLUMN()-3)) -> Absent | H9: =INDIRECT("RawData!"&ADDRESS(ROW(),COLUMN()-3)) -> Absent | I9: =INDIRECT("RawData!"&ADDRESS(ROW(),COLUMN()-3)) -> Absent | J9: =INDIRECT("RawData!"&ADDRESS(ROW(),COLUMN()-3)) -> Absent | K9: =INDIRECT("RawData!"&ADDRESS(ROW(),COLUMN()-3)) -> Absent | L9: =INDIRECT("RawData!"&ADDRESS(ROW(),COLUMN()-3)) -> Absent | ... LK9: =INDIRECT("RawData!"&ADDRESS(ROW(),COLUMN()-3))
A10: Mrs. Reshu Aggarwal | B10: 9728555776, 9896017210 | C10: https://lookerstudio.google.com/reporting/49c633d1-cab1-478b-95a6-791e684940f1 | D10: =INDIRECT("RawData!"&ADDRESS(ROW(),1)) -> Aarish Aggarwal | E10: =INDIRECT("RawData!"&ADDRESS(ROW(),COLUMN()-3)) -> 20 | F10: =INDIRECT("RawData!"&ADDRESS(ROW(),COLUMN()-3)) -> 50 | G10: =INDIRECT("RawData!"&ADDRESS(ROW(),COLUMN()-3)) -> 50 | H10: =INDIRECT("RawData!"&ADDRESS(ROW(),COLUMN()-3)) -> 45 | I10: =INDIRECT("RawData!"&ADDRESS(ROW(),COLUMN()-3)) -> 26 | J10: =INDIRECT("RawData!"&ADDRESS(ROW(),COLUMN()-3)) -> 36 | K10: =INDIRECT("RawData!"&ADDRESS(ROW(),COLUMN()-3)) -> 36 | L10: =INDIRECT("RawData!"&ADDRESS(ROW(),COLUMN()-3)) -> 50 | ... LK10: =INDIRECT("RawData!"&ADDRESS(ROW(),COLUMN()-3))
A11: Mrs. Khurana | B11: 8950126829 | C11: https://lookerstudio.google.com/reporting/cf9c4c6e-3c6c-4f42-bbf5-2b4ffe753537 | D11: =INDIRECT("RawData!"&ADDRESS(ROW(),1)) -> Aarna Khurana | E11: =INDIRECT("RawData!"&ADDRESS(ROW(),COLUMN()-3)) -> 20 | F11: =INDIRECT("RawData!"&ADDRESS(ROW(),COLUMN()-3)) -> 45 | G11: =INDIRECT("RawData!"&ADDRESS(ROW(),COLUMN()-3)) -> 46 | H11: =INDIRECT("RawData!"&ADDRESS(ROW(),COLUMN()-3)) -> 45 | I11: =INDIRECT("RawData!"&ADDRESS(ROW(),COLUMN()-3)) -> 22 | J11: =INDIRECT("RawData!"&ADDRESS(ROW(),COLUMN()-3)) -> 36 | K11: =INDIRECT("RawData!"&ADDRESS(ROW(),COLUMN()-3)) -> 34 | L11: =INDIRECT("RawData!"&ADDRESS(ROW(),COLUMN()-3)) -> 44 | ... LK11: =INDIRECT("RawData!"&ADDRESS(ROW(),COLUMN()-3))
A12: Mrs. Vishal Sahi | B12: 9996191918 | C12: https://lookerstudio.google.com/reporting/11b7db64-a589-4ee6-bce1-9bbd3fb2a073 | D12: =INDIRECT("RawData!"&ADDRESS(ROW(),1)) -> Aarush Sahi | E12: =INDIRECT("RawData!"&ADDRESS(ROW(),COLUMN()-3)) -> 18 | F12: =INDIRECT("RawData!"&ADDRESS(ROW(),COLUMN()-3)) -> 46 | G12: =INDIRECT("RawData!"&ADDRESS(ROW(),COLUMN()-3)) -> 48 | H12: =INDIRECT("RawData!"&ADDRESS(ROW(),COLUMN()-3)) -> 45 | I12: =INDIRECT("RawData!"&ADDRESS(ROW(),COLUMN()-3)) -> 25 | J12: =INDIRECT("RawData!"&ADDRESS(ROW(),COLUMN()-3)) -> 30 | K12: =INDIRECT("RawData!"&ADDRESS(ROW(),COLUMN()-3)) -> 30 | L12: =INDIRECT("RawData!"&ADDRESS(ROW(),COLUMN()-3)) -> 46 | ... LK12: =INDIRECT("RawData!"&ADDRESS(ROW(),COLUMN()-3))
A13: Mrs. Dimple . | B13: 9466019032 | C13: https://lookerstudio.google.com/reporting/a2ed09fb-acfa-4c43-9575-a94f14ff4535 | D13: =INDIRECT("RawData!"&ADDRESS(ROW(),1)) -> Aaryaveer | E13: =INDIRECT("RawData!"&ADDRESS(ROW(),COLUMN()-3)) -> 16 | F13: =INDIRECT("RawData!"&ADDRESS(ROW(),COLUMN()-3)) -> 48 | G13: =INDIRECT("RawData!"&ADDRESS(ROW(),COLUMN()-3)) -> 50 | H13: =INDIRECT("RawData!"&ADDRESS(ROW(),COLUMN()-3)) -> 33 | I13: =INDIRECT("RawData!"&ADDRESS(ROW(),COLUMN()-3)) -> 26 | J13: =INDIRECT("RawData!"&ADDRESS(ROW(),COLUMN()-3)) -> 26 | K13: =INDIRECT("RawData!"&ADDRESS(ROW(),COLUMN()-3)) -> 24 | L13: =INDIRECT("RawData!"&ADDRESS(ROW(),COLUMN()-3)) -> 50 | ... LK13: =INDIRECT("RawData!"&ADDRESS(ROW(),COLUMN()-3))
A14: Mrs. Karnika Aggarwal | B14: 9996631721 | C14: https://lookerstudio.google.com/reporting/e1a5e5a4-d165-4bc7-ab2d-a82c9cf4472c | D14: =INDIRECT("RawData!"&ADDRESS(ROW(),1)) -> Adhiraj Aggarwal | E14: =INDIRECT("RawData!"&ADDRESS(ROW(),COLUMN()-3)) -> Absent | F14: =INDIRECT("RawData!"&ADDRESS(ROW(),COLUMN()-3)) -> 50 | G14: =INDIRECT("RawData!"&ADDRESS(ROW(),COLUMN()-3)) -> 50 | H14: =INDIRECT("RawData!"&ADDRESS(ROW(),COLUMN()-3)) -> 45 | I14: =INDIRECT("RawData!"&ADDRESS(ROW(),COLUMN()-3)) -> 25 | J14: =INDIRECT("RawData!"&ADDRESS(ROW(),COLUMN()-3)) -> 36 | K14: =INDIRECT("RawData!"&ADDRESS(ROW(),COLUMN()-3)) -> 38 | L14: =INDIRECT("RawData!"&ADDRESS(ROW(),COLUMN()-3)) -> 50 | ... LK14: =INDIRECT("RawData!"&ADDRESS(ROW(),COLUMN()-3))
A15: Mrs. Shilpi Aggarwal | B15: 8295222342 | C15: https://lookerstudio.google.com/reporting/7b2b0988-047f-4ddc-96ed-0e844d1a5846 | D15: =INDIRECT("RawData!"&ADDRESS(ROW(),1)) -> Advik Kansal | E15: =INDIRECT("RawData!"&ADDRESS(ROW(),COLUMN()-3)) -> Absent | F15: =INDIRECT("RawData!"&ADDRESS(ROW(),COLUMN()-3)) -> 49 | G15: =INDIRECT("RawData!"&ADDRESS(ROW(),COLUMN()-3)) -> 50 | H15: =INDIRECT("RawData!"&ADDRESS(ROW(),COLUMN()-3)) -> 39 | I15: =INDIRECT("RawData!"&ADDRESS(ROW(),COLUMN()-3)) -> 22 | J15: =INDIRECT("RawData!"&ADDRESS(ROW(),COLUMN()-3)) -> 30 | K15: =INDIRECT("RawData!"&ADDRESS(ROW(),COLUMN()-3)) -> 36 | L15: =INDIRECT("RawData!"&ADDRESS(ROW(),COLUMN()-3)) -> 50 | ... LK15: =INDIRECT("RawData!"&ADDRESS(ROW(),COLUMN()-3))
A16: Mrs. Neelam Garg | B16: 9891688242 | C16: https://lookerstudio.google.com/reporting/efc396e8-8e27-4231-a3f3-12eb51470897 | D16: =INDIRECT("RawData!"&ADDRESS(ROW(),1)) -> Advika Garg | E16: =INDIRECT("RawData!"&ADDRESS(ROW(),COLUMN()-3)) -> 20 | F16: =INDIRECT("RawData!"&ADDRESS(ROW(),COLUMN()-3)) -> 41 | G16: =INDIRECT("RawData!"&ADDRESS(ROW(),COLUMN()-3)) -> 42 | H16: =INDIRECT("RawData!"&ADDRESS(ROW(),COLUMN()-3)) -> 39 | I16: =INDIRECT("RawData!"&ADDRESS(ROW(),COLUMN()-3)) -> 29 | J16: =INDIRECT("RawData!"&ADDRESS(ROW(),COLUMN()-3)) -> 34 | K16: =INDIRECT("RawData!"&ADDRESS(ROW(),COLUMN()-3)) -> 34 | L16: =INDIRECT("RawData!"&ADDRESS(ROW(),COLUMN()-3)) -> 44 | ... LK16: =INDIRECT("RawData!"&ADDRESS(ROW(),COLUMN()-3))
A17: Mr. Raman Kant Garg | B17: 9416000103 | C17: https://lookerstudio.google.com/reporting/14ca5783-b0be-4d35-97ea-613e85e98c23 | D17: =INDIRECT("RawData!"&ADDRESS(ROW(),1)) -> Akshita Garg | E17: =INDIRECT("RawData!"&ADDRESS(ROW(),COLUMN()-3)) -> 18 | F17: =INDIRECT("RawData!"&ADDRESS(ROW(),COLUMN()-3)) -> 50 | G17: =INDIRECT("RawData!"&ADDRESS(ROW(),COLUMN()-3)) -> 48 | H17: =INDIRECT("RawData!"&ADDRESS(ROW(),COLUMN()-3)) -> 36 | I17: =INDIRECT("RawData!"&ADDRESS(ROW(),COLUMN()-3)) -> 27 | J17: =INDIRECT("RawData!"&ADDRESS(ROW(),COLUMN()-3)) -> 32 | K17: =INDIRECT("RawData!"&ADDRESS(ROW(),COLUMN()-3)) -> 34 | L17: =INDIRECT("RawData!"&ADDRESS(ROW(),COLUMN()-3)) -> 46 | ... LK17: =INDIRECT("RawData!"&ADDRESS(ROW(),COLUMN()-3))
A18: Mrs. Deepti Arora | B18: 7404341175 | C18: https://lookerstudio.google.com/reporting/6d8241f7-c69b-435a-b6c5-2ee8c175dac3 | D18: =INDIRECT("RawData!"&ADDRESS(ROW(),1)) -> Amyra Arora | E18: =INDIRECT("RawData!"&ADDRESS(ROW(),COLUMN()-3)) -> 20 | F18: =INDIRECT("RawData!"&ADDRESS(ROW(),COLUMN()-3)) -> 50 | G18: =INDIRECT("RawData!"&ADDRESS(ROW(),COLUMN()-3)) -> 49 | H18: =INDIRECT("RawData!"&ADDRESS(ROW(),COLUMN()-3)) -> 42 | I18: =INDIRECT("RawData!"&ADDRESS(ROW(),COLUMN()-3)) -> 22 | J18: =INDIRECT("RawData!"&ADDRESS(ROW(),COLUMN()-3)) -> 38 | K18: =INDIRECT("RawData!"&ADDRESS(ROW(),COLUMN()-3)) -> 38 | L18: =INDIRECT("RawData!"&ADDRESS(ROW(),COLUMN()-3)) -> 46 | ... LK18: =INDIRECT("RawData!"&ADDRESS(ROW(),COLUMN()-3))
A19: Mrs. Shweta Jain | B19: 9896557779 | C19: https://lookerstudio.google.com/reporting/c36c07f7-64b7-4598-a43d-e3599b115963 | D19: =INDIRECT("RawData!"&ADDRESS(ROW(),1)) -> Arhat Jain | E19: =INDIRECT("RawData!"&ADDRESS(ROW(),COLUMN()-3)) -> 20 | F19: =INDIRECT("RawData!"&ADDRESS(ROW(),COLUMN()-3)) -> 50 | G19: =INDIRECT("RawData!"&ADDRESS(ROW(),COLUMN()-3)) -> 50 | H19: =INDIRECT("RawData!"&ADDRESS(ROW(),COLUMN()-3)) -> 39 | I19: =INDIRECT("RawData!"&ADDRESS(ROW(),COLUMN()-3)) -> 26 | J19: =INDIRECT("RawData!"&ADDRESS(ROW(),COLUMN()-3)) -> 36 | K19: =INDIRECT("RawData!"&ADDRESS(ROW(),COLUMN()-3)) -> 38 | L19: =INDIRECT("RawData!"&ADDRESS(ROW(),COLUMN()-3)) -> 48 | ... LK19: =INDIRECT("RawData!"&ADDRESS(ROW(),COLUMN()-3))
A20: Mrs. Kanwaljeet Kaur | B20: 9896786251 | C20: https://lookerstudio.google.com/reporting/6bd781b2-89ea-400d-b2c4-4bc5ee8d2d1b | D20: =INDIRECT("RawData!"&ADDRESS(ROW(),1)) -> Arshia Singh | E20: =INDIRECT("RawData!"&ADDRESS(ROW(),COLUMN()-3)) -> 18 | F20: =INDIRECT("RawData!"&ADDRESS(ROW(),COLUMN()-3)) -> 34 | G20: =INDIRECT("RawData!"&ADDRESS(ROW(),COLUMN()-3)) -> 32 | H20: =INDIRECT("RawData!"&ADDRESS(ROW(),COLUMN()-3)) -> 42 | I20: =INDIRECT("RawData!"&ADDRESS(ROW(),COLUMN()-3)) -> 21 | J20: =INDIRECT("RawData!"&ADDRESS(ROW(),COLUMN()-3)) -> Absent | K20: =INDIRECT("RawData!"&ADDRESS(ROW(),COLUMN()-3)) -> 28 | L20: =INDIRECT("RawData!"&ADDRESS(ROW(),COLUMN()-3)) -> 24 | ... LK20: =INDIRECT("RawData!"&ADDRESS(ROW(),COLUMN()-3))
A21: Mrs. Preeti Talwar | B21: 9896597107 | C21: https://lookerstudio.google.com/reporting/cd2c1f94-68d7-4905-a1b2-aeb4804840be | D21: =INDIRECT("RawData!"&ADDRESS(ROW(),1)) -> Bhavya Talwar | E21: =INDIRECT("RawData!"&ADDRESS(ROW(),COLUMN()-3)) -> 18 | F21: =INDIRECT("RawData!"&ADDRESS(ROW(),COLUMN()-3)) -> 49 | G21: =INDIRECT("RawData!"&ADDRESS(ROW(),COLUMN()-3)) -> 49 | H21: =INDIRECT("RawData!"&ADDRESS(ROW(),COLUMN()-3)) -> 42 | I21: =INDIRECT("RawData!"&ADDRESS(ROW(),COLUMN()-3)) -> 18 | J21: =INDIRECT("RawData!"&ADDRESS(ROW(),COLUMN()-3)) -> 34 | K21: =INDIRECT("RawData!"&ADDRESS(ROW(),COLUMN()-3)) -> 32 | L21: =INDIRECT("RawData!"&ADDRESS(ROW(),COLUMN()-3)) -> 50 | ... LK21: =INDIRECT("RawData!"&ADDRESS(ROW(),COLUMN()-3))
A22: Mrs. Maneeta Patnayak | B22: 8198064612, 9530909282 | C22: https://lookerstudio.google.com/reporting/abb34eb2-8998-45ad-98bf-a46a2d3da1e4 | D22: =INDIRECT("RawData!"&ADDRESS(ROW(),1)) -> Daksh Devgan | E22: =INDIRECT("RawData!"&ADDRESS(ROW(),COLUMN()-3)) -> 16 | F22: =INDIRECT("RawData!"&ADDRESS(ROW(),COLUMN()-3)) -> 48 | G22: =INDIRECT("RawData!"&ADDRESS(ROW(),COLUMN()-3)) -> 44 | H22: =INDIRECT("RawData!"&ADDRESS(ROW(),COLUMN()-3)) -> 42 | I22: =INDIRECT("RawData!"&ADDRESS(ROW(),COLUMN()-3)) -> Absent | J22: =INDIRECT("RawData!"&ADDRESS(ROW(),COLUMN()-3)) -> Absent | K22: =INDIRECT("RawData!"&ADDRESS(ROW(),COLUMN()-3)) -> 36 | L22: =INDIRECT("RawData!"&ADDRESS(ROW(),COLUMN()-3)) -> 46 | ... LK22: =INDIRECT("RawData!"&ADDRESS(ROW(),COLUMN()-3))
A23: Mrs. Anjali Gupta | B23: 9812115586 | C23: https://lookerstudio.google.com/reporting/97324455-7818-4c05-bea3-76c1ebd8b97e | D23: =INDIRECT("RawData!"&ADDRESS(ROW(),1)) -> Daksh Gupta | E23: =INDIRECT("RawData!"&ADDRESS(ROW(),COLUMN()-3)) -> 20 | F23: =INDIRECT("RawData!"&ADDRESS(ROW(),COLUMN()-3)) -> 50 | G23: =INDIRECT("RawData!"&ADDRESS(ROW(),COLUMN()-3)) -> 50 | H23: =INDIRECT("RawData!"&ADDRESS(ROW(),COLUMN()-3)) -> 45 | I23: =INDIRECT("RawData!"&ADDRESS(ROW(),COLUMN()-3)) -> 26 | J23: =INDIRECT("RawData!"&ADDRESS(ROW(),COLUMN()-3)) -> 28 | K23: =INDIRECT("RawData!"&ADDRESS(ROW(),COLUMN()-3)) -> 30 | L23: =INDIRECT("RawData!"&ADDRESS(ROW(),COLUMN()-3)) -> 50 | ... LK23: =INDIRECT("RawData!"&ADDRESS(ROW(),COLUMN()-3))
A24: Mrs. Rajni Chopra | B24: 7988727720 | C24: https://lookerstudio.google.com/reporting/d0904562-1f40-47f7-86a6-ac8fc3fc9e7c | D24: =INDIRECT("RawData!"&ADDRESS(ROW(),1)) -> Divyanshi Chopra | E24: =INDIRECT("RawData!"&ADDRESS(ROW(),COLUMN()-3)) -> 18 | F24: =INDIRECT("RawData!"&ADDRESS(ROW(),COLUMN()-3)) -> Absent | G24: =INDIRECT("RawData!"&ADDRESS(ROW(),COLUMN()-3)) -> 46 | H24: =INDIRECT("RawData!"&ADDRESS(ROW(),COLUMN()-3)) -> 42 | I24: =INDIRECT("RawData!"&ADDRESS(ROW(),COLUMN()-3)) -> 27 | J24: =INDIRECT("RawData!"&ADDRESS(ROW(),COLUMN()-3)) -> 38 | K24: =INDIRECT("RawData!"&ADDRESS(ROW(),COLUMN()-3)) -> 38 | L24: =INDIRECT("RawData!"&ADDRESS(ROW(),COLUMN()-3)) -> 49 | ... LK24: =INDIRECT("RawData!"&ADDRESS(ROW(),COLUMN()-3))
A25: Mrs. Isha Dang | B25: 8168694779 | C25: https://lookerstudio.google.com/reporting/aebab14f-0ece-40fa-8354-ce9196266c47 | D25: =INDIRECT("RawData!"&ADDRESS(ROW(),1)) -> Diya Dang | E25: =INDIRECT("RawData!"&ADDRESS(ROW(),COLUMN()-3)) -> 14 | F25: =INDIRECT("RawData!"&ADDRESS(ROW(),COLUMN()-3)) -> 48 | G25: =INDIRECT("RawData!"&ADDRESS(ROW(),COLUMN()-3)) -> 46 | H25: =INDIRECT("RawData!"&ADDRESS(ROW(),COLUMN()-3)) -> 36 | I25: =INDIRECT("RawData!"&ADDRESS(ROW(),COLUMN()-3)) -> 25 | J25: =INDIRECT("RawData!"&ADDRESS(ROW(),COLUMN()-3)) -> 28 | K25: =INDIRECT("RawData!"&ADDRESS(ROW(),COLUMN()-3)) -> 30 | L25: =INDIRECT("RawData!"&ADDRESS(ROW(),COLUMN()-3)) -> 50 | ... LK25: =INDIRECT("RawData!"&ADDRESS(ROW(),COLUMN()-3))
A26: Mrs. Ritu Bhatia | B26: 9253344818 | C26: https://lookerstudio.google.com/reporting/b851b9c2-257d-422a-b568-0af94dc68301 | D26: =INDIRECT("RawData!"&ADDRESS(ROW(),1)) -> Gyanda Sinha | E26: =INDIRECT("RawData!"&ADDRESS(ROW(),COLUMN()-3)) -> 20 | F26: =INDIRECT("RawData!"&ADDRESS(ROW(),COLUMN()-3)) -> 32 | G26: =INDIRECT("RawData!"&ADDRESS(ROW(),COLUMN()-3)) -> 41 | H26: =INDIRECT("RawData!"&ADDRESS(ROW(),COLUMN()-3)) -> 24 | I26: =INDIRECT("RawData!"&ADDRESS(ROW(),COLUMN()-3)) -> 24 | J26: =INDIRECT("RawData!"&ADDRESS(ROW(),COLUMN()-3)) -> 38 | K26: =INDIRECT("RawData!"&ADDRESS(ROW(),COLUMN()-3)) -> 38 | L26: =INDIRECT("RawData!"&ADDRESS(ROW(),COLUMN()-3)) -> 33 | ... LK26: =INDIRECT("RawData!"&ADDRESS(ROW(),COLUMN()-3))
A27: Mrs. Amandeep Sandhu | B27: 8930100322 | C27: https://lookerstudio.google.com/reporting/89ca82ef-bf50-4001-834c-a2ee984e4818 | D27: =INDIRECT("RawData!"&ADDRESS(ROW(),1)) -> Harseerat Sandhu | E27: =INDIRECT("RawData!"&ADDRESS(ROW(),COLUMN()-3)) -> Absent | F27: =INDIRECT("RawData!"&ADDRESS(ROW(),COLUMN()-3)) -> 40 | G27: =INDIRECT("RawData!"&ADDRESS(ROW(),COLUMN()-3)) -> 43 | H27: =INDIRECT("RawData!"&ADDRESS(ROW(),COLUMN()-3)) -> 24 | I27: =INDIRECT("RawData!"&ADDRESS(ROW(),COLUMN()-3)) -> 23 | J27: =INDIRECT("RawData!"&ADDRESS(ROW(),COLUMN()-3)) -> Absent | K27: =INDIRECT("RawData!"&ADDRESS(ROW(),COLUMN()-3)) -> 22 | L27: =INDIRECT("RawData!"&ADDRESS(ROW(),COLUMN()-3)) -> 38 | ... LK27: =INDIRECT("RawData!"&ADDRESS(ROW(),COLUMN()-3))
A28: Mrs. Debarati Verma | B28: 7980096133 | C28: https://lookerstudio.google.com/reporting/b3476863-2d9d-40ac-91ba-23a16979b1a9 | D28: =INDIRECT("RawData!"&ADDRESS(ROW(),1)) -> Hridaan Verma | E28: =INDIRECT("RawData!"&ADDRESS(ROW(),COLUMN()-3)) -> 22 | F28: =INDIRECT("RawData!"&ADDRESS(ROW(),COLUMN()-3)) -> 23 | G28: =INDIRECT("RawData!"&ADDRESS(ROW(),COLUMN()-3)) -> 34 | H28: =INDIRECT("RawData!"&ADDRESS(ROW(),COLUMN()-3)) -> 30 | I28: =INDIRECT("RawData!"&ADDRESS(ROW(),COLUMN()-3)) -> 19 | J28: =INDIRECT("RawData!"&ADDRESS(ROW(),COLUMN()-3)) -> 36 | K28: =INDIRECT("RawData!"&ADDRESS(ROW(),COLUMN()-3)) -> 34 | L28: =INDIRECT("RawData!"&ADDRESS(ROW(),COLUMN()-3)) -> 34 | ... LK28: =INDIRECT("RawData!"&ADDRESS(ROW(),COLUMN()-3))
A29: Mrs. Kanchan . | B29: 7206026283, 9988866883 | C29: https://lookerstudio.google.com/reporting/b95d2c90-5a73-4648-a83c-0a23479e84ed | D29: =INDIRECT("RawData!"&ADDRESS(ROW(),1)) -> Hrishita | E29: =INDIRECT("RawData!"&ADDRESS(ROW(),COLUMN()-3)) -> 18 | F29: =INDIRECT("RawData!"&ADDRESS(ROW(),COLUMN()-3)) -> 50 | G29: =INDIRECT("RawData!"&ADDRESS(ROW(),COLUMN()-3)) -> 50 | H29: =INDIRECT("RawData!"&ADDRESS(ROW(),COLUMN()-3)) -> 42 | I29: =INDIRECT("RawData!"&ADDRESS(ROW(),COLUMN()-3)) -> 25 | J29: =INDIRECT("RawData!"&ADDRESS(ROW(),COLUMN()-3)) -> 36 | K29: =INDIRECT("RawData!"&ADDRESS(ROW(),COLUMN()-3)) -> 30 | L29: =INDIRECT("RawData!"&ADDRESS(ROW(),COLUMN()-3)) -> 47 | ... LK29: =INDIRECT("RawData!"&ADDRESS(ROW(),COLUMN()-3))
A30: Mrs. Balbir Kaur | B30: 7357777774 | C30: https://lookerstudio.google.com/reporting/4df3aa31-10cb-4df0-8bd8-31a9a51e5ccd | D30: =INDIRECT("RawData!"&ADDRESS(ROW(),1)) -> Jasnoor Singh | E30: =INDIRECT("RawData!"&ADDRESS(ROW(),COLUMN()-3)) -> 16 | F30: =INDIRECT("RawData!"&ADDRESS(ROW(),COLUMN()-3)) -> Absent | G30: =INDIRECT("RawData!"&ADDRESS(ROW(),COLUMN()-3)) -> 20 | H30: =INDIRECT("RawData!"&ADDRESS(ROW(),COLUMN()-3)) -> 39 | I30: =INDIRECT("RawData!"&ADDRESS(ROW(),COLUMN()-3)) -> 19 | J30: =INDIRECT("RawData!"&ADDRESS(ROW(),COLUMN()-3)) -> 32 | K30: =INDIRECT("RawData!"&ADDRESS(ROW(),COLUMN()-3)) -> Absent | L30: =INDIRECT("RawData!"&ADDRESS(ROW(),COLUMN()-3)) -> Absent | ... LK30: =INDIRECT("RawData!"&ADDRESS(ROW(),COLUMN()-3))
A31: Mrs. Mansi Kochhar | B31: 9996698996 | C31: https://lookerstudio.google.com/reporting/257f03ab-4d06-470e-a43a-11d5bfcc2f52 | D31: =INDIRECT("RawData!"&ADDRESS(ROW(),1)) -> Kanhav Kochhar | E31: =INDIRECT("RawData!"&ADDRESS(ROW(),COLUMN()-3)) -> 18 | F31: =INDIRECT("RawData!"&ADDRESS(ROW(),COLUMN()-3)) -> Absent | G31: =INDIRECT("RawData!"&ADDRESS(ROW(),COLUMN()-3)) -> 50 | H31: =INDIRECT("RawData!"&ADDRESS(ROW(),COLUMN()-3)) -> 42 | I31: =INDIRECT("RawData!"&ADDRESS(ROW(),COLUMN()-3)) -> 20 | J31: =INDIRECT("RawData!"&ADDRESS(ROW(),COLUMN()-3)) -> 38 | K31: =INDIRECT("RawData!"&ADDRESS(ROW(),COLUMN()-3)) -> 36 | L31: =INDIRECT("RawData!"&ADDRESS(ROW(),COLUMN()-3)) -> 49 | ... LK31: =INDIRECT("RawData!"&ADDRESS(ROW(),COLUMN()-3))
A32: Mrs. Manpreet Kaur | B32: 9996014979 | C32: https://lookerstudio.google.com/reporting/f6b7c04b-9055-478e-81f2-ad7f47403861 | D32: =INDIRECT("RawData!"&ADDRESS(ROW(),1)) -> Karanveer Singh Gill | E32: =INDIRECT("RawData!"&ADDRESS(ROW(),COLUMN()-3)) -> 20 | F32: =INDIRECT("RawData!"&ADDRESS(ROW(),COLUMN()-3)) -> Absent | G32: =INDIRECT("RawData!"&ADDRESS(ROW(),COLUMN()-3)) -> 46 | H32: =INDIRECT("RawData!"&ADDRESS(ROW(),COLUMN()-3)) -> 45 | I32: =INDIRECT("RawData!"&ADDRESS(ROW(),COLUMN()-3)) -> 23 | J32: =INDIRECT("RawData!"&ADDRESS(ROW(),COLUMN()-3)) -> 34 | K32: =INDIRECT("RawData!"&ADDRESS(ROW(),COLUMN()-3)) -> Absent | L32: =INDIRECT("RawData!"&ADDRESS(ROW(),COLUMN()-3)) -> Absent | ... LK32: =INDIRECT("RawData!"&ADDRESS(ROW(),COLUMN()-3))
A33: Mr. Ashok | B33: 9729491167 | C33: https://lookerstudio.google.com/reporting/ff423a76-1f1c-407b-9253-d8f79479b14a | D33: =INDIRECT("RawData!"&ADDRESS(ROW(),1)) -> Khushi | E33: =INDIRECT("RawData!"&ADDRESS(ROW(),COLUMN()-3)) -> Absent | F33: =INDIRECT("RawData!"&ADDRESS(ROW(),COLUMN()-3)) -> Absent | G33: =INDIRECT("RawData!"&ADDRESS(ROW(),COLUMN()-3)) -> 43 | H33: =INDIRECT("RawData!"&ADDRESS(ROW(),COLUMN()-3)) -> 45 | I33: =INDIRECT("RawData!"&ADDRESS(ROW(),COLUMN()-3)) -> 22 | J33: =INDIRECT("RawData!"&ADDRESS(ROW(),COLUMN()-3)) -> 28 | K33: =INDIRECT("RawData!"&ADDRESS(ROW(),COLUMN()-3)) -> 34 | L33: =INDIRECT("RawData!"&ADDRESS(ROW(),COLUMN()-3)) -> 41 | ... LK33: =INDIRECT("RawData!"&ADDRESS(ROW(),COLUMN()-3))
A34: Mrs. Aditi Sharma | B34: 9810722685 | C34: https://datastudio.google.com/reporting/adab5166-faef-4e74-a2f3-dc553ce06da3 | D34: =INDIRECT("RawData!"&ADDRESS(ROW(),1)) -> Madhav Manan | E34: =INDIRECT("RawData!"&ADDRESS(ROW(),COLUMN()-3)) -> Absent | F34: =INDIRECT("RawData!"&ADDRESS(ROW(),COLUMN()-3)) -> Absent | G34: =INDIRECT("RawData!"&ADDRESS(ROW(),COLUMN()-3)) -> Absent | H34: =INDIRECT("RawData!"&ADDRESS(ROW(),COLUMN()-3)) -> Absent | I34: =INDIRECT("RawData!"&ADDRESS(ROW(),COLUMN()-3)) -> Absent | J34: =INDIRECT("RawData!"&ADDRESS(ROW(),COLUMN()-3)) -> Absent | K34: =INDIRECT("RawData!"&ADDRESS(ROW(),COLUMN()-3)) -> Absent | L34: =INDIRECT("RawData!"&ADDRESS(ROW(),COLUMN()-3)) -> Absent | ... LK34: =INDIRECT("RawData!"&ADDRESS(ROW(),COLUMN()-3))
A35: Mrs. Priyanka Judge | B35: 9810271983 | C35: https://lookerstudio.google.com/reporting/e7cc6b9b-c921-46c1-843c-b00f171bbe0f | D35: =INDIRECT("RawData!"&ADDRESS(ROW(),1)) -> Meher Judge | E35: =INDIRECT("RawData!"&ADDRESS(ROW(),COLUMN()-3)) -> 18 | F35: =INDIRECT("RawData!"&ADDRESS(ROW(),COLUMN()-3)) -> 37 | G35: =INDIRECT("RawData!"&ADDRESS(ROW(),COLUMN()-3)) -> 37 | H35: =INDIRECT("RawData!"&ADDRESS(ROW(),COLUMN()-3)) -> 42 | I35: =INDIRECT("RawData!"&ADDRESS(ROW(),COLUMN()-3)) -> 19 | J35: =INDIRECT("RawData!"&ADDRESS(ROW(),COLUMN()-3)) -> Absent | K35: =INDIRECT("RawData!"&ADDRESS(ROW(),COLUMN()-3)) -> 34 | L35: =INDIRECT("RawData!"&ADDRESS(ROW(),COLUMN()-3)) -> 32 | ... LK35: =INDIRECT("RawData!"&ADDRESS(ROW(),COLUMN()-3))
A36: Mrs. Bharti Minocha | B36: 9468474120 | C36: https://lookerstudio.google.com/reporting/3977d53d-b397-4fbf-88e3-2468bf7f56f6 | D36: =INDIRECT("RawData!"&ADDRESS(ROW(),1)) -> Namya Gogia | E36: =INDIRECT("RawData!"&ADDRESS(ROW(),COLUMN()-3)) -> 14 | F36: =INDIRECT("RawData!"&ADDRESS(ROW(),COLUMN()-3)) -> 36 | G36: =INDIRECT("RawData!"&ADDRESS(ROW(),COLUMN()-3)) -> Absent | H36: =INDIRECT("RawData!"&ADDRESS(ROW(),COLUMN()-3)) -> Absent | I36: =INDIRECT("RawData!"&ADDRESS(ROW(),COLUMN()-3)) -> 21 | J36: =INDIRECT("RawData!"&ADDRESS(ROW(),COLUMN()-3)) -> 26 | K36: =INDIRECT("RawData!"&ADDRESS(ROW(),COLUMN()-3)) -> 26 | L36: =INDIRECT("RawData!"&ADDRESS(ROW(),COLUMN()-3)) -> 22 | ... LK36: =INDIRECT("RawData!"&ADDRESS(ROW(),COLUMN()-3))
A37: Mrs. Neetu Kohli | B37: 7206087113 | C37: https://lookerstudio.google.com/reporting/25553b8f-19fe-4995-ba05-5e8779bf3552 | D37: =INDIRECT("RawData!"&ADDRESS(ROW(),1)) -> Navika Kohli | E37: =INDIRECT("RawData!"&ADDRESS(ROW(),COLUMN()-3)) -> 18 | F37: =INDIRECT("RawData!"&ADDRESS(ROW(),COLUMN()-3)) -> 48 | G37: =INDIRECT("RawData!"&ADDRESS(ROW(),COLUMN()-3)) -> 31 | H37: =INDIRECT("RawData!"&ADDRESS(ROW(),COLUMN()-3)) -> 27 | I37: =INDIRECT("RawData!"&ADDRESS(ROW(),COLUMN()-3)) -> 17 | J37: =INDIRECT("RawData!"&ADDRESS(ROW(),COLUMN()-3)) -> Absent | K37: =INDIRECT("RawData!"&ADDRESS(ROW(),COLUMN()-3)) -> 34 | L37: =INDIRECT("RawData!"&ADDRESS(ROW(),COLUMN()-3)) -> 39 | ... LK37: =INDIRECT("RawData!"&ADDRESS(ROW(),COLUMN()-3))
A38: Mrs. Jain | B38: 9729498393 | C38: https://lookerstudio.google.com/reporting/eb925af1-1493-4aee-abe2-dceec57e6df3 | D38: =INDIRECT("RawData!"&ADDRESS(ROW(),1)) -> Nishchay Jain | E38: =INDIRECT("RawData!"&ADDRESS(ROW(),COLUMN()-3)) -> 18 | F38: =INDIRECT("RawData!"&ADDRESS(ROW(),COLUMN()-3)) -> 48 | G38: =INDIRECT("RawData!"&ADDRESS(ROW(),COLUMN()-3)) -> 39 | H38: =INDIRECT("RawData!"&ADDRESS(ROW(),COLUMN()-3)) -> 45 | I38: =INDIRECT("RawData!"&ADDRESS(ROW(),COLUMN()-3)) -> 17 | J38: =INDIRECT("RawData!"&ADDRESS(ROW(),COLUMN()-3)) -> Absent | K38: =INDIRECT("RawData!"&ADDRESS(ROW(),COLUMN()-3)) -> 28 | L38: =INDIRECT("RawData!"&ADDRESS(ROW(),COLUMN()-3)) -> 47 | ... LK38: =INDIRECT("RawData!"&ADDRESS(ROW(),COLUMN()-3))
A39: Mrs. Asha Rani | B39: 9466601861 | C39: https://lookerstudio.google.com/reporting/6c17ed98-b846-45b6-96f1-ece4b3dd7729 | D39: =INDIRECT("RawData!"&ADDRESS(ROW(),1)) -> Nitya S Verma | E39: =INDIRECT("RawData!"&ADDRESS(ROW(),COLUMN()-3)) -> 20 | F39: =INDIRECT("RawData!"&ADDRESS(ROW(),COLUMN()-3)) -> 29 | G39: =INDIRECT("RawData!"&ADDRESS(ROW(),COLUMN()-3)) -> 44 | H39: =INDIRECT("RawData!"&ADDRESS(ROW(),COLUMN()-3)) -> 45 | I39: =INDIRECT("RawData!"&ADDRESS(ROW(),COLUMN()-3)) -> 22 | J39: =INDIRECT("RawData!"&ADDRESS(ROW(),COLUMN()-3)) -> 36 | K39: =INDIRECT("RawData!"&ADDRESS(ROW(),COLUMN()-3)) -> 30 | L39: =INDIRECT("RawData!"&ADDRESS(ROW(),COLUMN()-3)) -> 38 | ... LK39: =INDIRECT("RawData!"&ADDRESS(ROW(),COLUMN()-3))
A40: Mrs. Mamta Verma | B40: 9654959026 | C40: https://lookerstudio.google.com/reporting/d371376d-b420-4607-906f-639b22348572 | D40: =INDIRECT("RawData!"&ADDRESS(ROW(),1)) -> Pranav Verma | E40: =INDIRECT("RawData!"&ADDRESS(ROW(),COLUMN()-3)) -> 20 | F40: =INDIRECT("RawData!"&ADDRESS(ROW(),COLUMN()-3)) -> 48 | G40: =INDIRECT("RawData!"&ADDRESS(ROW(),COLUMN()-3)) -> 44 | H40: =INDIRECT("RawData!"&ADDRESS(ROW(),COLUMN()-3)) -> 36 | I40: =INDIRECT("RawData!"&ADDRESS(ROW(),COLUMN()-3)) -> 29 | J40: =INDIRECT("RawData!"&ADDRESS(ROW(),COLUMN()-3)) -> Absent | K40: =INDIRECT("RawData!"&ADDRESS(ROW(),COLUMN()-3)) -> 32 | L40: =INDIRECT("RawData!"&ADDRESS(ROW(),COLUMN()-3)) -> 48 | ... LK40: =INDIRECT("RawData!"&ADDRESS(ROW(),COLUMN()-3))
...

Sheet WhatsApp Send Log
A1: Timestamp | B1: Test Number | C1: Test Column | D1: Test Date | E1: Student Name | F1: Phone Number | G1: Dashboard Link | H1: Status | I1: Message ID | J1: Error (if any) | K1: Protected
A2: 46120.497 | B2: 1 | C2: E1 | D2: 46118 | E2: Aadit Jain | F2: 919802080000 | G2: https://lookerstudio.google.com/reporting/1d4419ee-1be6-46ab-a94d-51a23019b02b | H2: SENT | I2: wamid.HBgMOTE5ODAyMDgwMDAwFQIAERgSQkJBRjYzMjFCMTMwRUJBNEY0AA== | K2: No
A3: 46120.497 | B3: 1 | C3: E1 | D3: 46118 | E3: Aahaan Verma | F3: 919416204259 | G3: https://lookerstudio.google.com/reporting/837c8441-222f-4199-8bde-5064633a41de | H3: SENT | I3: wamid.HBgMOTE5NDE2MjA0MjU5FQIAERgSQzEwREVFOTRFMTAyQjNDRkQ0AA== | K3: No
A4: 46120.497 | B4: 1 | C4: E1 | D4: 46118 | E4: Aakhya Verma | F4: 919813557570 | G4: https://lookerstudio.google.com/reporting/f1faf766-7e0c-4d87-8056-42e5b6b82bda | H4: SENT | I4: wamid.HBgMOTE5ODEzNTU3NTcwFQIAERgSQkYyNDE5MzZENDFERDRGM0YzAA== | K4: No
A5: 46120.497 | B5: 1 | C5: E1 | D5: 46118 | E5: Aaradhya Yadav | F5: 919728634214 | G5: https://lookerstudio.google.com/reporting/12200997-d65b-4b0f-be0f-736ce813f5a1 | H5: SENT | I5: wamid.HBgMOTE5NzI4NjM0MjE0FQIAERgSMDlGMkVENzU4OUZDNTFCNjI4AA== | K5: No
A6: 46120.497 | B6: 1 | C6: E1 | D6: 46118 | E6: Aaradhya Yadav | F6: 919053935556 | G6: https://lookerstudio.google.com/reporting/12200997-d65b-4b0f-be0f-736ce813f5a1 | H6: SENT | I6: wamid.HBgMOTE5MDUzOTM1NTU2FQIAERgSRDYzQjg0RjgxNDI2QjZBN0QzAA== | K6: No
A7: 46120.497 | B7: 1 | C7: E1 | D7: 46118 | E7: Aarav Dutta | F7: 918168736926 | G7: https://lookerstudio.google.com/reporting/64859623-f473-443c-a144-c4c23c0f4b59 | H7: SENT | I7: wamid.HBgMOTE4MTY4NzM2OTI2FQIAERgSMzRCNTA5MzA4NUQ5OEZFMEExAA== | K7: No
A8: 46120.497 | B8: 1 | C8: E1 | D8: 46118 | E8: Aarish Aggarwal | F8: 919728555776 | G8: https://lookerstudio.google.com/reporting/49c633d1-cab1-478b-95a6-791e684940f1 | H8: SENT | I8: wamid.HBgMOTE5NzI4NTU1Nzc2FQIAERgSMEU0NzQ2QzU1ODYzRUQwODQ2AA== | K8: No
A9: 46120.497 | B9: 1 | C9: E1 | D9: 46118 | E9: Aarna Khurana | F9: 918950126829 | G9: https://lookerstudio.google.com/reporting/cf9c4c6e-3c6c-4f42-bbf5-2b4ffe753537 | H9: SENT | I9: wamid.HBgMOTE4OTUwMTI2ODI5FQIAERgSQThDNjhENkM5MUIzMzY3MUJEAA== | K9: No
A10: 46120.497 | B10: 1 | C10: E1 | D10: 46118 | E10: Aarush Sahi | F10: 919996191918 | G10: https://lookerstudio.google.com/reporting/11b7db64-a589-4ee6-bce1-9bbd3fb2a073 | H10: SENT | I10: wamid.HBgMOTE5OTk2MTkxOTE4FQIAERgSMDZFOUI1NjdGRTgwQ0ZEOUJEAA== | K10: No
A11: 46120.497 | B11: 1 | C11: E1 | D11: 46118 | E11: Aaryaveer | F11: 919466019032 | G11: https://lookerstudio.google.com/reporting/a2ed09fb-acfa-4c43-9575-a94f14ff4535 | H11: SENT | I11: wamid.HBgMOTE5NDY2MDE5MDMyFQIAERgSMzlDRTBGRkREQ0RBNTAyM0Y5AA== | K11: No
A12: 46120.498 | B12: 1 | C12: E1 | D12: 46118 | E12: Abhimanyu Chauhan | F12: 918199990333 | G12: https://lookerstudio.google.com/reporting/458785c0-cc24-4f30-94ce-640c66349cd6 | H12: SENT | I12: wamid.HBgMOTE4MTk5OTkwMzMzFQIAERgSNEY4RTNBOTcwQURFQjJDNjdCAA== | K12: No
A13: 46120.498 | B13: 1 | C13: E1 | D13: 46118 | E13: Adhiraj Aggarwal | F13: 919996631721 | G13: https://lookerstudio.google.com/reporting/e1a5e5a4-d165-4bc7-ab2d-a82c9cf4472c | H13: SENT - ABSENT | K13: No
A14: 46120.498 | B14: 1 | C14: E1 | D14: 46118 | E14: Advik Kansal | F14: 918295222342 | G14: https://lookerstudio.google.com/reporting/7b2b0988-047f-4ddc-96ed-0e844d1a5846 | H14: SENT - ABSENT | K14: No
