Workbook
Name LatestScores_Class9: RawData!$BH$6:$BH$67

Sheet RawData
A1: T | B1: 9
A2: Date | B2: 46118 | C2: 46118 | D2: 46120.727 | E2: 46120 | F2: 46120 | G2: 46121 | H2: 46122 | I2: 46122 | J2: 46126 | K2: 46126 | L2: 46128 | M2: 46128 | N2: 46129 | O2: 46131 | P2: 46131 | Q2: 46133 | R2: 46135 | S2: 46135 | T2: 46141 | U2: 46141 | V2: 46144 | W2: 46146 | X2: 46147 | Y2: 46147 | Z2: 46149 | AA2: 46153 | AB2: 46153 | AC2: 46153 | AD2: 46155 | AE2: 46157 | AF2: 46158 | AG2: 46158 | AH2: 46153 | AI2: 46153 | AJ2: 46161 | AK2: 46161 | AL2: 46161 | AM2: 46162 | AN2: 46163 | AO2: 46164 | AP2: 46167 | AQ2: 46167 | AR2: 46167 | AS2: 46167 | AT2: 46170 | AU2: 46171 | AV2: 46172 | AW2: 46175 | AX2: 46175 | AY2: 46177 | AZ2: 46178 | BA2: 46178 | BB2: 46178 | BC2: 46178 | BD2: 46178 | BE2: 46178 | BF2: 46178 | BG2: 46177 | BH2: 46183
A3: Subject | B3: Science | C3: Maths | D3: Science | E3: Maths | F3: Maths | G3: Science | H3: Science | I3: Maths | J3: Maths | K3: Maths | L3: Science | M3: Maths | N3: Maths | O3: Maths | P3: Science | Q3: Science | R3: Science | S3: Science | T3: Science | U3: Science | V3: Science | W3: Science | X3: Science | Y3: Maths | Z3: Science | AA3: Maths | AB3: Maths | AC3: Maths | AD3: Science | AE3: Science | AF3: Science | AG3: Maths | AH3: Maths | AI3: Maths | AJ3: Science | AK3: Science | AL3: Maths | AM3: Science | AN3: Science | AO3: Science | AP3: Science | AQ3: Science | AR3: Science | AS3: Science | AT3: Maths | AU3: Science | AV3: Maths | AW3: Science | AX3: Maths | AY3: Science | AZ3: Maths | BA3: Maths | BB3: Maths | BC3: Science | BD3: Maths | BE3: Science | BF3: Science | BG3: Science | BH3: Maths
A4: Total Marks | B4: 24 | C4: 40 | D4: 24 | E4: 40 | F4: 40 | G4: 40 | H4: 45 | I4: 40 | J4: 34 | K4: 20 | L4: 40 | M4: 34 | N4: 38 | O4: 40 | P4: 38 | Q4: 56 | R4: 28 | S4: 56 | T4: 30 | U4: 35 | V4: 40 | W4: 40 | X4: 40 | Y4: 40 | Z4: 40 | AA4: 38 | AB4: 40 | AC4: 36 | AD4: 35 | AE4: 50 | AF4: 38 | AG4: 35 | AH4: 25 | AI4: 25 | AJ4: 38 | AK4: 50 | AL4: 35 | AM4: 58 | AN4: 60 | AO4: 40 | AP4: 45 | AQ4: 40 | AR4: 95 | AS4: 58 | AT4: 35 | AU4: 55 | AV4: 35 | AW4: 40 | AX4: 38 | AY4: 40 | AZ4: 20 | BA4: 40 | BB4: 60 | BC4: 80 | BD4: 40 | BE4: 40 | BF4: 60 | BG4: 20 | BH4: 40
A5: Topic Name | B5: Cell: The Building Block of Life | C5: Orienting Yourself: The Use of Coordinates | D5: Cell: The Building Block of Life | E5: Orienting Yourself: The Use of Coordinates | F5: Orienting Yourself: The Use of Coordinates | G5: Cell: The Building Block of Life | H5: Cell: The Building Block of Life | I5: Orienting Yourself: The Use of Coordinates | J5: Introduction to Linear Polynomials | K5: Orienting Yourself: The Use of Coordinates | L5: Describing Motion Around Us | M5: Introduction to Linear Polynomials | N5: Introduction to Linear Polynomials | O5: Orienting Yourself: The Use of Coordinates | P5: Cell: The Building Block of Life | Q5: Exploring Mixtures and their Separation | R5: Describing Motion Around Us | S5: Exploring Mixtures and their Separation | T5: Describing Motion Around Us | U5: Cell: The Building Block of Life | V5: Cell: The Building Block of Life | W5: Cell: The Building Block of Life | X5: Cell: The Building Block of Life | Y5: The World of Numbers | Z5: Describing Motion Around Us | AA5: Introduction to Linear Polynomials | AB5: The World of Numbers | AC5: Orienting Yourself: The Use of Coordinates | AD5: Cell: The Building Block of Life | AE5: Cell: The Building Block of Life | AF5: Cell: The Building Block of Life | AG5: The World of Numbers | AH5: Orienting Yourself: The Use of Coordinates | AI5: Measuring Space: Perimeter and Area | AJ5: Cell: The Building Block of Life | AK5: Cell: The Building Block of Life | AL5: The World of Numbers | AM5: Cell: The Building Block of Life | AN5: Cell: The Building Block of Life | AO5: Describing Motion Around Us | AP5: Describing Motion Around Us | AQ5: Exploring Mixtures and their Separation | AR5: Cell: The Building Block of Life | AS5: Exploring Mixtures and their Separation | AT5: The World of Numbers | AU5: Describing Motion Around Us | AV5: The World of Numbers | AW5: Describing Motion Around Us | AX5: The World of Numbers | AY5: Describing Motion Around Us | AZ5: Measuring Space: Perimeter and Area | BA5: Introduction to Linear Polynomials | BB5: The World of Numbers | BC5: Cell: The Building Block of Life | BD5: Orienting Yourself: The Use of Coordinates | BE5: Exploring Mixtures and their Separation | BF5: Describing Motion Around Us | BG5: Describing Motion Around Us | BH5: Introduction to Linear Polynomials
A6: Aabhav Aggarwal | B6: 20 | C6: 40 | D6: 22 | E6: 38 | F6: 34 | G6: 36 | H6: 38 | I6: 36 | J6: 30 | K6: 18 | L6: 38 | M6: 32 | N6: 34 | O6: 38 | P6: 38 | Q6: 50 | R6: 24 | S6: 54 | T6: 24 | U6: 32 | V6: 36 | W6: 34 | X6: 36 | Y6: 36 | Z6: 38 | AA6: 26 | AB6: 36 | AC6: 34 | AD6: 22 | AE6: 36 | AF6: 26 | AG6: 26 | AH6: 25 | AI6: 19 | AJ6: 32 | AK6: 46 | AL6: 35 | AM6: 54 | AN6: 52 | AO6: 40 | AP6: 40 | AQ6: 38 | AR6: 94 | AS6: 54 | AT6: 27 | AU6: 51 | AV6: 35 | AW6: 34 | AX6: 36 | AY6: 40 | AZ6: 20 | BA6: 38 | BB6: 52 | BC6: 66 | BD6: 40 | BE6: 38 | BF6: 58 | BG6: 17 | BH6: Absent
A7: Aanya Aggarwal | B7: Absent | C7: Absent | D7: Absent | E7: Absent | F7: Absent | G7: 30 | H7: 32 | I7: 26 | J7: 32 | K7: 20 | L7: 28 | M7: 30 | N7: 34 | O7: 32 | P7: 34 | Q7: 46 | R7: 16 | S7: 38 | T7: 24 | U7: 35 | V7: 36 | W7: 32 | X7: 40 | Y7: 36 | Z7: 30 | AA7: Absent | AB7: Absent | AC7: Absent | AD7: Absent | AE7: 26 | AF7: 30 | AG7: 26 | AH7: Absent | AI7: Absent | AJ7: 30 | AK7: 34 | AL7: 22 | AM7: 46 | AN7: 50 | AO7: 32 | AP7: 34 | AQ7: 30 | AR7: 92 | AS7: 50 | AT7: 20 | AU7: 37 | AV7: 28 | AW7: 30 | AX7: 30 | AY7: 28 | AZ7: 18 | BA7: 38 | BB7: 56 | BC7: 66 | BD7: 36 | BE7: 28 | BF7: 48 | BG7: 18 | BH7: Absent
A8: Aarav Bansal | B8: 22 | C8: 38 | D8: 24 | E8: 40 | F8: 38 | G8: 38 | H8: 44 | I8: 38 | J8: 32 | K8: 20 | L8: 38 | M8: 30 | N8: 34 | O8: 38 | P8: 36 | Q8: 48 | R8: 24 | S8: 53 | T8: 28 | U8: 33 | V8: 30 | W8: 32 | X8: 32 | Y8: 38 | Z8: 32 | AA8: 32 | AB8: 40 | AC8: 32 | AD8: 24 | AE8: 34 | AF8: 32 | AG8: 30 | AH8: 21 | AI8: 13 | AJ8: 28 | AK8: 42 | AL8: 32 | AM8: 46 | AN8: 48 | AO8: 40 | AP8: 34 | AQ8: 36 | AR8: 90 | AS8: 46 | AT8: 28 | AU8: 45 | AV8: 31 | AW8: Absent | AX8: Absent | AY8: Absent | AZ8: Absent | BA8: Absent | BB8: Absent | BC8: Absent | BD8: Absent | BE8: Absent | BF8: Absent | BG8: Absent | BH8: Absent
A9: Aashi Gupta | B9: 22 | C9: 22 | D9: 22 | E9: 32 | F9: 32 | G9: 38 | H9: 38 | I9: 32 | J9: 24 | K9: 11 | L9: 26 | M9: 28 | N9: 28 | O9: Absent | P9: Absent | Q9: 46 | R9: 12 | S9: 50 | T9: 18 | U9: 34 | V9: Absent | W9: 24 | X9: 26 | Y9: 23 | Z9: 26 | AA9: 32 | AB9: 28 | AC9: 24 | AD9: 28 | AE9: 42 | AF9: 36 | AG9: 19 | AH9: 17 | AI9: 16 | AJ9: 30 | AK9: 48 | AL9: 17 | AM9: 40 | AN9: 46 | AO9: 32 | AP9: 18 | AQ9: 32 | AR9: 86 | AS9: 42 | AT9: 18 | AU9: 37 | AV9: 16 | AW9: 24 | AX9: 32 | AY9: 32 | AZ9: 8 | BA9: 40 | BB9: 42 | BC9: 66 | BD9: 30 | BE9: 22 | BF9: 50 | BG9: 18 | BH9: 32
A10: Aashray Maken | B10: 14 | C10: 30 | D10: 18 | E10: 28 | F10: 20 | G10: 18 | H10: 30 | I10: 30 | J10: 26 | K10: 13 | L10: 22 | M10: 26 | N10: 26 | O10: 34 | P10: 24 | Q10: 28 | R10: 14 | S10: 36 | T10: 20 | U10: 28 | V10: 30 | W10: 26 | X10: 32 | Y10: 19 | Z10: 22 | AA10: 20 | AB10: 21 | AC10: 28 | AD10: 18 | AE10: 24 | AF10: 26 | AG10: 23 | AH10: 14 | AI10: 13 | AJ10: 28 | AK10: 32 | AL10: 15 | AM10: 32 | AN10: 44 | AO10: 24 | AP10: 18 | AQ10: 26 | AR10: 70 | AS10: 26 | AT10: 16 | AU10: 22 | AV10: 20 | AW10: 16 | AX10: 22 | AY10: 26 | AZ10: 8 | BA10: 38 | BB10: 40 | BC10: 48 | BD10: 34 | BE10: 22 | BF10: 36 | BG10: 9 | BH10: 30
A11: Adaa Kataria | B11: Absent | C11: Absent | D11: Absent | E11: Absent | F11: Absent | G11: Absent | H11: Absent | I11: Absent | J11: Absent | K11: Absent | L11: Absent | M11: Absent | N11: Absent | O11: Absent | P11: Absent | Q11: Absent | R11: Absent | S11: Absent | T11: 12 | U11: 18 | V11: 22 | W11: 22 | X11: 22 | Y11: 17 | Z11: 20 | AA11: Absent | AB11: Absent | AC11: Absent | AD11: Absent | AE11: 20 | AF11: 18 | AG11: 16 | AH11: Absent | AI11: Absent | AJ11: 20 | AK11: 32 | AL11: 14 | AM11: 30 | AN11: 24 | AO11: 16 | AP11: 18 | AQ11: 26 | AR11: 48 | AS11: 24 | AT11: 17 | AU11: Absent | AV11: 14 | AW11: Absent | AX11: Absent | AY11: 16 | AZ11: 8 | BA11: 20 | BB11: 38 | BC11: 36 | BD11: 16 | BE11: 22 | BF11: 24 | BG11: 7 | BH11: 22
A12: Adhiraj Dhall | B12: 22 | C12: 40 | D12: 22 | E12: 36 | F12: 40 | G12: 36 | H12: 34 | I12: 38 | J12: 28 | K12: 20 | L12: 32 | M12: 32 | N12: 38 | O12: 40 | P12: 38 | Q12: 56 | R12: 28 | S12: 56 | T12: 28 | U12: 35 | V12: 38 | W12: 40 | X12: 40 | Y12: 34 | Z12: 36 | AA12: 38 | AB12: 38 | AC12: 32 | AD12: 30 | AE12: 46 | AF12: 36 | AG12: 28 | AH12: 25 | AI12: 20 | AJ12: 32 | AK12: 50 | AL12: 35 | AM12: 50 | AN12: 50 | AO12: 40 | AP12: 45 | AQ12: 36 | AR12: 88 | AS12: 56 | AT12: 27 | AU12: 53 | AV12: 27 | AW12: 32 | AX12: 26 | AY12: 38 | AZ12: Absent | BA12: Absent | BB12: Absent | BC12: Absent | BD12: Absent | BE12: Absent | BF12: Absent | BG12: 19 | BH12: Absent
A13: Agamya Saini | B13: Absent | C13: Absent | D13: Absent | E13: Absent | F13: Absent | G13: Absent | H13: Absent | I13: Absent | J13: Absent | K13: Absent | L13: Absent | M13: Absent | N13: Absent | O13: Absent | P13: Absent | Q13: Absent | R13: Absent | S13: Absent | T13: Absent | U13: Absent | V13: Absent | W13: Absent | X13: 16 | Y13: 16 | Z13: 22 | AA13: 24 | AB13: 27 | AC13: 15 | AD13: 28 | AE13: 38 | AF13: 18 | AG13: 25 | AH13: 11 | AI13: 11 | AJ13: 28 | AK13: 44 | AL13: 27 | AM13: 44 | AN13: 56 | AO13: 24 | AP13: 32 | AQ13: 40 | AR13: 74 | AS13: 48 | AT13: 28 | AU13: 38 | AV13: 32 | AW13: 32 | AX13: 30 | AY13: Absent | AZ13: Absent | BA13: Absent | BB13: Absent | BC13: Absent | BD13: Absent | BE13: Absent | BF13: Absent | BG13: Absent | BH13: 30
A14: Akshat Singh | B14: 22 | C14: 40 | D14: 24 | E14: 34 | F14: 16 | G14: 36 | H14: 36 | I14: 32 | J14: 26 | K14: 18 | L14: 30 | M14: 28 | N14: 36 | O14: 38 | P14: 38 | Q14: 48 | R14: 24 | S14: 50 | T14: 28 | U14: 32 | V14: 30 | W14: 36 | X14: 36 | Y14: 34 | Z14: 30 | AA14: 34 | AB14: 38 | AC14: 30 | AD14: 22 | AE14: 38 | AF14: 22 | AG14: 24 | AH14: 20 | AI14: 20 | AJ14: 24 | AK14: 40 | AL14: 32 | AM14: 46 | AN14: 44 | AO14: 32 | AP14: 45 | AQ14: 40 | AR14: 82 | AS14: 48 | AT14: 26 | AU14: 51 | AV14: 31 | AW14: 36 | AX14: 30 | AY14: 34 | AZ14: 20 | BA14: 36 | BB14: 58 | BC14: 58 | BD14: 38 | BE14: 36 | BF14: 52 | BG14: 15 | BH14: 38
A15: Ameya Goel | B15: Absent | C15: Absent | D15: Absent | E15: Absent | F15: Absent | G15: Absent | H15: Absent | I15: Absent | J15: Absent | K15: Absent | L15: 24 | M15: 24 | N15: 26 | O15: 16 | P15: 18 | Q15: Absent | R15: 16 | S15: 30 | T15: 24 | U15: 26 | V15: 16 | W15: Absent | X15: 16 | Y15: 34 | Z15: 30 | AA15: Absent | AB15: Absent | AC15: Absent | AD15: Absent | AE15: Absent | AF15: Absent | AG15: Absent | AH15: Absent | AI15: Absent | AJ15: 16 | AK15: 26 | AL15: 17 | AM15: 30 | AN15: 36 | AO15: 32 | AP15: 30 | AQ15: 24 | AR15: 64 | AS15: 30 | AT15: 14 | AU15: 40 | AV15: 27 | AW15: 18 | AX15: 28 | AY15: 34 | AZ15: 8 | BA15: 36 | BB15: 50 | BC15: 58 | BD15: 16 | BE15: 26 | BF15: 50 | BG15: 5 | BH15: 32
A16: Anay Arora | B16: 16 | C16: 28 | D16: 16 | E16: 26 | F16: 22 | G16: 24 | H16: 30 | I16: 26 | J16: 24 | K16: 12 | L16: 22 | M16: 26 | N16: 30 | O16: 32 | P16: 28 | Q16: 23 | R16: 14 | S16: 34 | T16: Absent | U16: Absent | V16: 28 | W16: Absent | X16: Absent | Y16: Absent | Z16: Absent | AA16: Absent | AB16: Absent | AC16: Absent | AD16: 14 | AE16: Absent | AF16: Absent | AG16: Absent | AH16: Absent | AI16: Absent | AJ16: Absent | AK16: Absent | AL16: Absent | AM16: Absent | AN16: Absent | AO16: Absent | AP16: 18 | AQ16: 16 | AR16: 38 | AS16: 28 | AT16: 14 | AU16: 22 | AV16: Absent | AW16: 24 | AX16: 16 | AY16: 30 | AZ16: 8 | BA16: 38 | BB16: 38 | BC16: 36 | BD16: 36 | BE16: 16 | BF16: 24 | BG16: 5 | BH16: Absent
A17: Arnav Goel | B17: 24 | C17: 38 | D17: 24 | E17: 38 | F17: 34 | G17: 30 | H17: 32 | I17: 38 | J17: 34 | K17: 20 | L17: 36 | M17: 32 | N17: 38 | O17: 40 | P17: 34 | Q17: 44 | R17: 26 | S17: 52 | T17: 30 | U17: 32 | V17: 34 | W17: 32 | X17: 36 | Y17: 34 | Z17: 34 | AA17: 38 | AB17: 36 | AC17: 30 | AD17: 18 | AE17: 36 | AF17: 30 | AG17: 25 | AH17: 18 | AI17: 22 | AJ17: 32 | AK17: 42 | AL17: 35 | AM17: 50 | AN17: 52 | AO17: 40 | AP17: 44 | AQ17: 32 | AR17: 90 | AS17: 54 | AT17: 33 | AU17: 42 | AV17: 33 | AW17: 16 | AX17: 38 | AY17: 38 | AZ17: 18 | BA17: 38 | BB17: 54 | BC17: 76 | BD17: 36 | BE17: 40 | BF17: 60 | BG17: 17 | BH17: 38
A18: Arnav Mehndiratta | B18: Absent | C18: Absent | D18: Absent | E18: Absent | F18: Absent | G18: Absent | H18: Absent | I18: Absent | J18: Absent | K18: Absent | L18: Absent | M18: Absent | N18: Absent | O18: Absent | P18: Absent | Q18: Absent | R18: Absent | S18: Absent | T18: Absent | U18: Absent | V18: Absent | W18: Absent | X18: Absent | Y18: Absent | Z18: Absent | AA18: Absent | AB18: Absent | AC18: Absent | AD18: Absent | AE18: Absent | AF18: Absent | AG18: Absent | AH18: Absent | AI18: Absent | AJ18: Absent | AK18: Absent | AL18: Absent | AM18: Absent | AN18: Absent | AO18: Absent | AP18: Absent | AQ18: Absent | AR18: Absent | AS18: Absent | AT18: Absent | AU18: Absent | AV18: Absent | AW18: 26 | AX18: 16 | AY18: Absent | AZ18: Absent | BA18: Absent | BB18: Absent | BC18: Absent | BD18: Absent | BE18: Absent | BF18: Absent | BG18: Absent | BH18: 38
A19: Arnav Saxena | B19: 22 | C19: 38 | D19: 24 | E19: 40 | F19: 38 | G19: 38 | H19: 44 | I19: 38 | J19: 32 | K19: 20 | L19: 38 | M19: 30 | N19: 36 | O19: 38 | P19: 38 | Q19: 56 | R19: 28 | S19: 56 | T19: 30 | U19: 35 | V19: 38 | W19: 40 | X19: 40 | Y19: 36 | Z19: 38 | AA19: 32 | AB19: 36 | AC19: 32 | AD19: 34 | AE19: 50 | AF19: 36 | AG19: 33 | AH19: 21 | AI19: 22 | AJ19: 32 | AK19: 48 | AL19: 32 | AM19: 56 | AN19: 54 | AO19: 40 | AP19: 45 | AQ19: 40 | AR19: 92 | AS19: 58 | AT19: 31 | AU19: 55 | AV19: 35 | AW19: 40 | AX19: 36 | AY19: 40 | AZ19: 20 | BA19: 40 | BB19: 54 | BC19: 70 | BD19: 38 | BE19: 38 | BF19: 60 | BG19: 17 | BH19: 38
A20: Atharv Aggarwal | B20: 20 | C20: 36 | D20: 20 | E20: 38 | F20: 36 | G20: 34 | H20: 44 | I20: 36 | J20: 30 | K20: 20 | L20: 40 | M20: 32 | N20: 38 | O20: 36 | P20: 38 | Q20: 54 | R20: 28 | S20: 56 | T20: 30 | U20: 32 | V20: 34 | W20: 38 | X20: 38 | Y20: 36 | Z20: Absent | AA20: 36 | AB20: 38 | AC20: 36 | AD20: 32 | AE20: 46 | AF20: 34 | AG20: 33 | AH20: 23 | AI20: 19 | AJ20: 32 | AK20: 42 | AL20: 35 | AM20: 36 | AN20: 38 | AO20: 38 | AP20: 45 | AQ20: 40 | AR20: 92 | AS20: 58 | AT20: 33 | AU20: 51 | AV20: 30 | AW20: 38 | AX20: 28 | AY20: 36 | AZ20: Absent | BA20: Absent | BB20: Absent | BC20: Absent | BD20: Absent | BE20: Absent | BF20: Absent | BG20: 18 | BH20: 36
A21: Avni Chhabra | B21: 22 | C21: 30 | D21: 24 | E21: 36 | F21: 28 | G21: 24 | H21: 32 | I21: 28 | J21: 22 | K21: 13 | L21: 28 | M21: 28 | N21: 28 | O21: 34 | P21: 36 | Q21: 44 | R21: 14 | S21: 48 | T21: 18 | U21: 30 | V21: 32 | W21: 32 | X21: 32 | Y21: 27 | Z21: 26 | AA21: 24 | AB21: 27 | AC21: 18 | AD21: 20 | AE21: 40 | AF21: 38 | AG21: 30 | AH21: 18 | AI21: 14 | AJ21: 38 | AK21: 48 | AL21: 23 | AM21: 56 | AN21: 56 | AO21: 28 | AP21: 24 | AQ21: 40 | AR21: 82 | AS21: 50 | AT21: 20 | AU21: 34 | AV21: Absent | AW21: 32 | AX21: 28 | AY21: 32 | AZ21: Absent | BA21: Absent | BB21: Absent | BC21: Absent | BD21: Absent | BE21: Absent | BF21: Absent | BG21: 9 | BH21: Absent
A22: Ayaan Guglani | B22: 22 | C22: 38 | D22: 24 | E22: 36 | F22: 38 | G22: 32 | H22: 38 | I22: 38 | J22: 28 | K22: 20 | L22: 30 | M22: 30 | N22: 36 | O22: 40 | P22: 34 | Q22: 50 | R22: 20 | S22: 42 | T22: 26 | U22: 34 | V22: 36 | W22: 36 | X22: 34 | Y22: 34 | Z22: 30 | AA22: 34 | AB22: 40 | AC22: 34 | AD22: 28 | AE22: 48 | AF22: 32 | AG22: 30 | AH22: 21 | AI22: 19 | AJ22: 36 | AK22: 46 | AL22: 32 | AM22: 52 | AN22: 52 | AO22: 36 | AP22: 41 | AQ22: 40 | AR22: 86 | AS22: 54 | AT22: Absent | AU22: 45 | AV22: 35 | AW22: 30 | AX22: 26 | AY22: 36 | AZ22: 18 | BA22: 32 | BB22: 60 | BC22: 74 | BD22: 36 | BE22: 34 | BF22: 54 | BG22: 16 | BH22: Absent
A23: Ayaan Singh | B23: 20 | C23: 40 | D23: 24 | E23: 40 | F23: 34 | G23: 38 | H23: 45 | I23: 36 | J23: 26 | K23: 19 | L23: 38 | M23: 34 | N23: 36 | O23: 38 | P23: 38 | Q23: 50 | R23: 26 | S23: 54 | T23: 30 | U23: 35 | V23: 34 | W23: 40 | X23: 40 | Y23: 34 | Z23: 36 | AA23: Absent | AB23: Absent | AC23: Absent | AD23: Absent | AE23: 46 | AF23: 32 | AG23: 31 | AH23: Absent | AI23: Absent | AJ23: 36 | AK23: 44 | AL23: 32 | AM23: 54 | AN23: 58 | AO23: 36 | AP23: 43 | AQ23: 38 | AR23: 90 | AS23: 50 | AT23: 24 | AU23: 45 | AV23: Absent | AW23: 28 | AX23: 32 | AY23: 38 | AZ23: 18 | BA23: 40 | BB23: 58 | BC23: 76 | BD23: 36 | BE23: 40 | BF23: 58 | BG23: 17 | BH23: Absent
A24: Ayush Kumar | B24: 10 | C24: 20 | D24: 16 | E24: 18 | F24: 16 | G24: 22 | H24: 18 | I24: 16 | J24: 24 | K24: 13 | L24: 22 | M24: 22 | N24: 28 | O24: 32 | P24: 32 | Q24: 23 | R24: 12 | S24: 23 | T24: 16 | U24: 20 | V24: 28 | W24: Absent | X24: 16 | Y24: 16 | Z24: 16 | AA24: 22 | AB24: Absent | AC24: 18 | AD24: 14 | AE24: 20 | AF24: 16 | AG24: 14 | AH24: 13 | AI24: 2 | AJ24: 16 | AK24: 20 | AL24: 14 | AM24: 24 | AN24: 24 | AO24: 26 | AP24: 18 | AQ24: 16 | AR24: 38 | AS24: 24 | AT24: 14 | AU24: 22 | AV24: 14 | AW24: 16 | AX24: 16 | AY24: 16 | AZ24: 8 | BA24: 38 | BB24: 24 | BC24: 36 | BD24: 24 | BE24: 16 | BF24: 38 | BG24: 2 | BH24: 24
A25: Bhavik Katoch | B25: 22 | C25: 36 | D25: 24 | E25: 36 | F25: 38 | G25: 34 | H25: 42 | I25: 38 | J25: 28 | K25: 15 | L25: 36 | M25: 32 | N25: 34 | O25: 40 | P25: 38 | Q25: 52 | R25: 28 | S25: 52 | T25: 28 | U25: 30 | V25: 30 | W25: 32 | X25: 34 | Y25: 23 | Z25: 34 | AA25: 36 | AB25: 30 | AC25: 28 | AD25: 32 | AE25: 36 | AF25: 28 | AG25: 30 | AH25: 21 | AI25: 20 | AJ25: 30 | AK25: 36 | AL25: 32 | AM25: 48 | AN25: Absent | AO25: Absent | AP25: 42 | AQ25: 38 | AR25: 78 | AS25: 56 | AT25: 28 | AU25: 51 | AV25: Absent | AW25: Absent | AX25: Absent | AY25: Absent | AZ25: Absent | BA25: Absent | BB25: Absent | BC25: Absent | BD25: Absent | BE25: Absent | BF25: Absent | BG25: Absent | BH25: Absent
A26: Bhavya Chawla | B26: 22 | C26: 24 | D26: 20 | E26: 36 | F26: 40 | G26: 30 | H26: 32 | I26: 38 | J26: 26 | K26: 19 | L26: 30 | M26: 32 | N26: 36 | O26: 40 | P26: 34 | Q26: 52 | R26: 22 | S26: 50 | T26: 26 | U26: 35 | V26: 34 | W26: 32 | X26: 38 | Y26: 34 | Z26: 26 | AA26: 32 | AB26: 34 | AC26: 32 | AD26: 28 | AE26: 42 | AF26: 28 | AG26: 25 | AH26: 18 | AI26: 22 | AJ26: Absent | AK26: Absent | AL26: Absent | AM26: Absent | AN26: Absent | AO26: 34 | AP26: 37 | AQ26: 40 | AR26: 88 | AS26: 58 | AT26: 24 | AU26: 45 | AV26: 28 | AW26: 28 | AX26: 34 | AY26: 40 | AZ26: 16 | BA26: 40 | BB26: 54 | BC26: 60 | BD26: 36 | BE26: 38 | BF26: 56 | BG26: 20 | BH26: 36
A27: Bhuvi Chauhan | B27: 20 | C27: 40 | D27: 24 | E27: 40 | F27: 38 | G27: 38 | H27: 36 | I27: 40 | J27: 32 | K27: 19 | L27: 30 | M27: 34 | N27: Absent | O27: Absent | P27: Absent | Q27: 34 | R27: 18 | S27: 44 | T27: 24 | U27: 34 | V27: 36 | W27: 40 | X27: 40 | Y27: 40 | Z27: 28 | AA27: 30 | AB27: 38 | AC27: 32 | AD27: 34 | AE27: 50 | AF27: 38 | AG27: 33 | AH27: 25 | AI27: 21 | AJ27: 36 | AK27: 50 | AL27: 29 | AM27: 58 | AN27: 58 | AO27: 34 | AP27: 38 | AQ27: 32 | AR27: 92 | AS27: 50 | AT27: 31 | AU27: 37 | AV27: Absent | AW27: Absent | AX27: Absent | AY27: 30 | AZ27: Absent | BA27: Absent | BB27: Absent | BC27: Absent | BD27: Absent | BE27: Absent | BF27: Absent | BG27: 18 | BH27: 38
A28: Chahat Sehgal | B28: Absent | C28: 16 | D28: 16 | E28: 24 | F28: 28 | G28: 16 | H28: 30 | I28: 16 | J28: 28 | K28: 17 | L28: 26 | M28: 22 | N28: 34 | O28: 32 | P28: 34 | Q28: 46 | R28: 12 | S28: 46 | T28: 24 | U28: 24 | V28: 30 | W28: 16 | X28: 28 | Y28: 27 | Z28: 28 | AA28: 32 | AB28: 27 | AC28: 28 | AD28: Absent | AE28: Absent | AF28: Absent | AG28: Absent | AH28: 16 | AI28: 14 | AJ28: 26 | AK28: 28 | AL28: 24 | AM28: 28 | AN28: 36 | AO28: 30 | AP28: 22 | AQ28: 30 | AR28: 72 | AS28: 48 | AT28: 22 | AU28: 26 | AV28: Absent | AW28: 24 | AX28: 28 | AY28: 34 | AZ28: 12 | BA28: 38 | BB28: 56 | BC28: 64 | BD28: 30 | BE28: 32 | BF28: 50 | BG28: 17 | BH28: 32
A29: Chhavi Saini | B29: Absent | C29: Absent | D29: Absent | E29: Absent | F29: Absent | G29: Absent | H29: Absent | I29: Absent | J29: Absent | K29: Absent | L29: 16 | M29: 20 | N29: 28 | O29: 16 | P29: 16 | Q29: 48 | R29: 12 | S29: 54 | T29: 22 | U29: 28 | V29: 30 | W29: 24 | X29: 28 | Y29: 38 | Z29: 16 | AA29: 24 | AB29: 34 | AC29: 15 | AD29: 20 | AE29: Absent | AF29: 28 | AG29: 23 | AH29: 18 | AI29: 12 | AJ29: 30 | AK29: 38 | AL29: 29 | AM29: 44 | AN29: 50 | AO29: 28 | AP29: 34 | AQ29: 28 | AR29: 78 | AS29: 56 | AT29: 17 | AU29: 42 | AV29: Absent | AW29: 28 | AX29: 22 | AY29: 30 | AZ29: 20 | BA29: 34 | BB29: 48 | BC29: 66 | BD29: 32 | BE29: 38 | BF29: 52 | BG29: 17 | BH29: 38
A30: Daksh Julka | B30: 16 | C30: 34 | D30: 18 | E30: 36 | F30: 28 | G30: 30 | H30: 34 | I30: 28 | J30: 32 | K30: 17 | L30: 26 | M30: 28 | N30: 36 | O30: 36 | P30: 30 | Q30: 46 | R30: 18 | S30: 44 | T30: 24 | U30: 26 | V30: 34 | W30: 36 | X30: 40 | Y30: 29 | Z30: 20 | AA30: 30 | AB30: 32 | AC30: 28 | AD30: 26 | AE30: Absent | AF30: 22 | AG30: 28 | AH30: 16 | AI30: 4 | AJ30: 26 | AK30: 34 | AL30: 26 | AM30: 32 | AN30: 36 | AO30: 34 | AP30: 18 | AQ30: 26 | AR30: 76 | AS30: 42 | AT30: 26 | AU30: 32 | AV30: 24 | AW30: 16 | AX30: 26 | AY30: 26 | AZ30: 8 | BA30: 32 | BB30: 50 | BC30: 60 | BD30: 34 | BE30: 22 | BF30: 52 | BG30: 16 | BH30: Absent
A31: Devishee Nayar | B31: 22 | C31: 40 | D31: 24 | E31: 40 | F31: 36 | G31: Absent | H31: Absent | I31: Absent | J31: 24 | K31: 15 | L31: 34 | M31: 28 | N31: 36 | O31: 38 | P31: 38 | Q31: 48 | R31: 24 | S31: 52 | T31: 30 | U31: 35 | V31: 30 | W31: 34 | X31: 36 | Y31: 40 | Z31: 32 | AA31: 30 | AB31: 38 | AC31: 36 | AD31: 28 | AE31: 50 | AF31: 38 | AG31: 33 | AH31: 21 | AI31: 16 | AJ31: 38 | AK31: 48 | AL31: 29 | AM31: 50 | AN31: 56 | AO31: Absent | AP31: 41 | AQ31: 36 | AR31: 80 | AS31: 40 | AT31: Absent | AU31: Absent | AV31: 31 | AW31: 34 | AX31: 32 | AY31: 38 | AZ31: Absent | BA31: Absent | BB31: Absent | BC31: Absent | BD31: Absent | BE31: Absent | BF31: Absent | BG31: 18 | BH31: Absent
A32: Devishi Gupta | B32: 24 | C32: 40 | D32: 24 | E32: 38 | F32: 40 | G32: 36 | H32: 36 | I32: 40 | J32: 32 | K32: 20 | L32: 32 | M32: 30 | N32: 38 | O32: 40 | P32: 38 | Q32: 54 | R32: 20 | S32: 54 | T32: 26 | U32: 32 | V32: 38 | W32: 36 | X32: 40 | Y32: 38 | Z32: 34 | AA32: 30 | AB32: 38 | AC32: 32 | AD32: 32 | AE32: 46 | AF32: 36 | AG32: 35 | AH32: 24 | AI32: 23 | AJ32: 28 | AK32: 46 | AL32: 32 | AM32: 52 | AN32: 54 | AO32: 36 | AP32: 45 | AQ32: 40 | AR32: 88 | AS32: 56 | AT32: 33 | AU32: 46 | AV32: 33 | AW32: 16 | AX32: 38 | AY32: 38 | AZ32: 20 | BA32: 38 | BB32: 60 | BC32: 70 | BD32: 36 | BE32: 38 | BF32: 56 | BG32: 18 | BH32: 40
A33: Fateh Partap Singh | B33: Absent | C33: Absent | D33: Absent | E33: Absent | F33: Absent | G33: Absent | H33: Absent | I33: Absent | J33: Absent | K33: Absent | L33: Absent | M33: Absent | N33: Absent | O33: Absent | P33: Absent | Q33: Absent | R33: Absent | S33: Absent | T33: Absent | U33: Absent | V33: Absent | W33: Absent | X33: Absent | Y33: Absent | Z33: Absent | AA33: Absent | AB33: Absent | AC33: Absent | AD33: Absent | AE33: Absent | AF33: Absent | AG33: Absent | AH33: Absent | AI33: Absent | AJ33: Absent | AK33: Absent | AL33: Absent | AM33: Absent | AN33: Absent | AO33: Absent | AP33: Absent | AQ33: Absent | AR33: Absent | AS33: Absent | AT33: Absent | AU33: Absent | AV33: Absent | AW33: 12 | AX33: 10 | AY33: 16 | AZ33: 6 | BA33: 32 | BB33: 26 | BC33: 22 | BD33: 20 | BE33: 20 | BF33: 24 | BG33: 11 | BH33: 26
A34: Japnidh Singh | B34: 24 | C34: 40 | D34: 24 | E34: 40 | F34: 36 | G34: 36 | H34: 38 | I34: 40 | J34: 30 | K34: 20 | L34: 40 | M34: 32 | N34: 38 | O34: 40 | P34: 38 | Q34: 56 | R34: 28 | S34: 54 | T34: 30 | U34: 35 | V34: Absent | W34: 34 | X34: 38 | Y34: 40 | Z34: 34 | AA34: 36 | AB34: 40 | AC34: 32 | AD34: 26 | AE34: 46 | AF34: 32 | AG34: 30 | AH34: 15 | AI34: 19 | AJ34: Absent | AK34: Absent | AL34: Absent | AM34: 54 | AN34: 52 | AO34: 34 | AP34: Absent | AQ34: Absent | AR34: Absent | AS34: Absent | AT34: 35 | AU34: Absent | AV34: 35 | AW34: 36 | AX34: 36 | AY34: 40 | AZ34: 20 | BA34: 36 | BB34: 54 | BC34: 64 | BD34: 38 | BE34: 34 | BF34: 32 | BG34: 20 | BH34: Absent
A35: Jaskeerat Kaur | B35: 22 | C35: 40 | D35: 22 | E35: 40 | F35: 38 | G35: 38 | H35: 40 | I35: 36 | J35: 28 | K35: 14 | L35: 38 | M35: 34 | N35: 36 | O35: 40 | P35: 38 | Q35: 48 | R35: 20 | S35: 56 | T35: 28 | U35: 34 | V35: 40 | W35: 38 | X35: 40 | Y35: 36 | Z35: 34 | AA35: 34 | AB35: 34 | AC35: 34 | AD35: 35 | AE35: 50 | AF35: Absent | AG35: Absent | AH35: 15 | AI35: 21 | AJ35: 38 | AK35: 48 | AL35: 35 | AM35: 56 | AN35: Absent | AO35: 36 | AP35: Absent | AQ35: Absent | AR35: Absent | AS35: Absent | AT35: 29 | AU35: 46 | AV35: 31 | AW35: 34 | AX35: 32 | AY35: 34 | AZ35: 18 | BA35: 38 | BB35: 60 | BC35: 64 | BD35: 38 | BE35: 16 | BF35: 60 | BG35: 16 | BH35: 40
A36: Jigar | B36: Absent | C36: Absent | D36: Absent | E36: Absent | F36: Absent | G36: 22 | H36: 24 | I36: 16 | J36: 24 | K36: 10 | L36: 34 | M36: 24 | N36: 34 | O36: 32 | P36: 20 | Q36: 38 | R36: 14 | S36: 42 | T36: 26 | U36: 32 | V36: 32 | W36: 24 | X36: 26 | Y36: 33 | Z36: 34 | AA36: 24 | AB36: 34 | AC36: 28 | AD36: 16 | AE36: 20 | AF36: 18 | AG36: 28 | AH36: 23 | AI36: 12 | AJ36: 26 | AK36: 32 | AL36: 21 | AM36: 40 | AN36: Absent | AO36: Absent | AP36: 33 | AQ36: 18 | AR36: 68 | AS36: 44 | AT36: 26 | AU36: 30 | AV36: Absent | AW36: 34 | AX36: 24 | AY36: 32 | AZ36: Absent | BA36: Absent | BB36: Absent | BC36: Absent | BD36: Absent | BE36: Absent | BF36: Absent | BG36: 7 | BH36: Absent
A37: Jivanshi | B37: Absent | C37: Absent | D37: Absent | E37: Absent | F37: Absent | G37: Absent | H37: Absent | I37: Absent | J37: Absent | K37: Absent | L37: Absent | M37: Absent | N37: Absent | O37: Absent | P37: Absent | Q37: Absent | R37: Absent | S37: Absent | T37: Absent | U37: Absent | V37: Absent | W37: 16 | X37: 28 | Y37: 21 | Z37: 28 | AA37: Absent | AB37: Absent | AC37: Absent | AD37: 32 | AE37: 46 | AF37: 22 | AG37: 19 | AH37: Absent | AI37: Absent | AJ37: 34 | AK37: 50 | AL37: 15 | AM37: 56 | AN37: 56 | AO37: 16 | AP37: 18 | AQ37: 16 | AR37: 86 | AS37: 24 | AT37: 14 | AU37: 34 | AV37: Absent | AW37: 20 | AX37: 16 | AY37: 20 | AZ37: 16 | BA37: 30 | BB37: 34 | BC37: 32 | BD37: 16 | BE37: 16 | BF37: 24 | BG37: 5 | BH37: 22
A38: Kanishk Singh | B38: 20 | C38: 24 | D38: 18 | E38: 30 | F38: 16 | G38: 38 | H38: 32 | I38: 16 | J38: 28 | K38: 11 | L38: 24 | M38: 26 | N38: 30 | O38: 32 | P38: 34 | Q38: 36 | R38: 14 | S38: 40 | T38: 18 | U38: 26 | V38: 32 | W38: 28 | X38: 30 | Y38: 36 | Z38: 24 | AA38: 22 | AB38: 38 | AC38: 28 | AD38: Absent | AE38: 20 | AF38: 26 | AG38: 14 | AH38: 16 | AI38: 2 | AJ38: 22 | AK38: 34 | AL38: 21 | AM38: 42 | AN38: 46 | AO38: Absent | AP38: 18 | AQ38: 24 | AR38: 62 | AS38: 30 | AT38: 18 | AU38: 23 | AV38: 22 | AW38: 16 | AX38: 20 | AY38: 24 | AZ38: Absent | BA38: Absent | BB38: Absent | BC38: Absent | BD38: Absent | BE38: Absent | BF38: Absent | BG38: 7 | BH38: Absent
A39: Kartik Gupta | B39: 24 | C39: 40 | D39: 24 | E39: 38 | F39: 40 | G39: 38 | H39: 45 | I39: 38 | J39: 34 | K39: 20 | L39: 40 | M39: 34 | N39: 38 | O39: 40 | P39: 38 | Q39: 54 | R39: 26 | S39: 56 | T39: 30 | U39: 34 | V39: 38 | W39: 38 | X39: 38 | Y39: 40 | Z39: 34 | AA39: 34 | AB39: 38 | AC39: 34 | AD39: 34 | AE39: Absent | AF39: 38 | AG39: 33 | AH39: 24 | AI39: 22 | AJ39: 38 | AK39: 48 | AL39: 35 | AM39: 46 | AN39: 56 | AO39: 40 | AP39: 45 | AQ39: 34 | AR39: 95 | AS39: 56 | AT39: 35 | AU39: 53 | AV39: 33 | AW39: 40 | AX39: 38 | AY39: 40 | AZ39: 20 | BA39: 40 | BB39: 56 | BC39: 76 | BD39: 40 | BE39: 40 | BF39: 60 | BG39: 7 | BH39: Absent
A40: Kavish Batra | B40: 20 | C40: 34 | D40: 24 | E40: 38 | F40: 40 | G40: 36 | H40: 38 | I40: 40 | J40: 30 | K40: 19 | L40: 34 | M40: 34 | N40: 36 | O40: 40 | P40: 38 | Q40: 54 | R40: 22 | S40: 52 | T40: 30 | U40: 35 | V40: 38 | W40: 40 | X40: 40 | Y40: 36 | Z40: 30 | AA40: 38 | AB40: 36 | AC40: 32 | AD40: 32 | AE40: 50 | AF40: 34 | AG40: 28 | AH40: 15 | AI40: 19 | AJ40: 34 | AK40: 48 | AL40: 32 | AM40: 52 | AN40: 56 | AO40: 38 | AP40: 42 | AQ40: 38 | AR40: 95 | AS40: 50 | AT40: 33 | AU40: 39 | AV40: 33 | AW40: 30 | AX40: 34 | AY40: 40 | AZ40: 18 | BA40: 38 | BB40: 56 | BC40: 66 | BD40: 34 | BE40: 40 | BF40: 60 | BG40: 16 | BH40: 38
...

Sheet Chapters
A1: Chapters
A2: Orienting Yourself: The Use of Coordinates
A3: Introduction to Linear Polynomials
A4: The World of Numbers
A5: Exploring Algebraic Identities
A6: I’m Up and Down, and Round and Round
A7: Measuring Space: Perimeter and Area
A8: The Mathematics of Maybe: Introduction to Probability
A9: Predicting What Comes Next: Exploring Sequences and Progression
A10: Maths Full Syllabus
A11: Exploration: Entering the World of Secondary Science
A12: Cell: The Building Block of Life
... A24: Science Full Syllabus

Sheet Whatsapp Scores Notification Sh
C1: 📊 Dashboard | D1: Whatsapp Send Button
C2: Dashboard Link | D2: =RawData!$A2 -> Date | E2: =RawData!B2 -> 46118 | F2: =RawData!C2 -> 46118 | G2: =RawData!D2 -> 46120.727 | H2: =RawData!E2 -> 46120 | I2: =RawData!F2 -> 46120 | J2: =RawData!G2 -> 46121 | K2: =RawData!H2 -> 46122 | L2: =RawData!I2 -> 46122 | ... KS2: =RawData!KP2
C3: Student Dashboard | D3: =RawData!$A3 -> Subject | E3: =RawData!B3 -> Science | F3: =RawData!C3 -> Maths | G3: =RawData!D3 -> Science | H3: =RawData!E3 -> Maths | I3: =RawData!F3 -> Maths | J3: =RawData!G3 -> Science | K3: =RawData!H3 -> Science | L3: =RawData!I3 -> Maths | ... KS3: =RawData!KP3
C4: Looker Studio | D4: =RawData!$A4 -> Total Marks | E4: =RawData!B4 -> 24 | F4: =RawData!C4 -> 40 | G4: =RawData!D4 -> 24 | H4: =RawData!E4 -> 40 | I4: =RawData!F4 -> 40 | J4: =RawData!G4 -> 40 | K4: =RawData!H4 -> 45 | L4: =RawData!I4 -> 40 | ... KS4: =RawData!KP4
A5: Parent Name | B5: Phone Number | C5: Dashboard Link | D5: =RawData!$A5 -> Topic Name | E5: =RawData!B5 -> Cell: The Building Block of Life | F5: =RawData!C5 -> Orienting Yourself: The Use of Coordinates | G5: =RawData!D5 -> Cell: The Building Block of Life | H5: =RawData!E5 -> Orienting Yourself: The Use of Coordinates | I5: =RawData!F5 -> Orienting Yourself: The Use of Coordinates | J5: =RawData!G5 -> Cell: The Building Block of Life | K5: =RawData!H5 -> Cell: The Building Block of Life | L5: =RawData!I5 -> Orienting Yourself: The Use of Coordinates | ... AP5: =RawData!AM5 -> Cell: The Building Block of Life | AQ5: Cell: The Building Block of Life | AR5: =RawData!AO5 -> Describing Motion Around Us | AS5: =RawData!AP5 -> Describing Motion Around Us | AT5: =RawData!AQ5 -> Exploring Mixtures and their Separation | AU5: =RawData!AR5 -> Cell: The Building Block of Life | AV5: =RawData!AS5 -> Exploring Mixtures and their Separation | AW5: =RawData!AT5 -> The World of Numbers | AX5: =RawData!AU5 -> Describing Motion Around Us | AY5: =RawData!AV5 -> The World of Numbers | AZ5: =RawData!AW5 -> Describing Motion Around Us | BA5: The World of Numbers | BB5: Describing Motion Around Us | BC5: =RawData!AZ5 -> Measuring Space: Perimeter and Area | BD5: =RawData!BA5 -> Introduction to Linear Polynomials | BE5: =RawData!BB5 -> The World of Numbers | BF5: =RawData!BC5 -> Cell: The Building Block of Life | BG5: =RawData!BD5 -> Orienting Yourself: The Use of Coordinates | BH5: =RawData!BE5 -> Exploring Mixtures and their Separation | BI5: =RawData!BF5 -> Describing Motion Around Us | BJ5: =RawData!BG5 -> Describing Motion Around Us | ... KS5: =RawData!KP5
A6: Mr. Nitin Aggarwal | B6: 9416177674 | C6: https://lookerstudio.google.com/reporting/b56c7bd8-a855-4974-8118-cd4cd2779f96 | D6: =INDIRECT("RawData!"&ADDRESS(ROW(),1)) -> Aabhav Aggarwal | E6: =INDIRECT("RawData!"&ADDRESS(ROW(),COLUMN()-3)) -> 20 | F6: =INDIRECT("RawData!"&ADDRESS(ROW(),COLUMN()-3)) -> 40 | G6: =INDIRECT("RawData!"&ADDRESS(ROW(),COLUMN()-3)) -> 22 | H6: =INDIRECT("RawData!"&ADDRESS(ROW(),COLUMN()-3)) -> 38 | I6: =INDIRECT("RawData!"&ADDRESS(ROW(),COLUMN()-3)) -> 34 | J6: =INDIRECT("RawData!"&ADDRESS(ROW(),COLUMN()-3)) -> 36 | K6: =INDIRECT("RawData!"&ADDRESS(ROW(),COLUMN()-3)) -> 38 | L6: =INDIRECT("RawData!"&ADDRESS(ROW(),COLUMN()-3)) -> 36 | ... KS6: =INDIRECT("RawData!"&ADDRESS(ROW(),COLUMN()-3))
A7: Mrs. Mukta Aggarwal | B7: 9896191613 | C7: https://datastudio.google.com/reporting/99cfe018-ad13-4ca2-b779-0529def9eee8 | D7: =INDIRECT("RawData!"&ADDRESS(ROW(),1)) -> Aanya Aggarwal | E7: =INDIRECT("RawData!"&ADDRESS(ROW(),COLUMN()-3)) -> Absent | F7: =INDIRECT("RawData!"&ADDRESS(ROW(),COLUMN()-3)) -> Absent | G7: =INDIRECT("RawData!"&ADDRESS(ROW(),COLUMN()-3)) -> Absent | H7: =INDIRECT("RawData!"&ADDRESS(ROW(),COLUMN()-3)) -> Absent | I7: =INDIRECT("RawData!"&ADDRESS(ROW(),COLUMN()-3)) -> Absent | J7: =INDIRECT("RawData!"&ADDRESS(ROW(),COLUMN()-3)) -> 30 | K7: =INDIRECT("RawData!"&ADDRESS(ROW(),COLUMN()-3)) -> 32 | L7: =INDIRECT("RawData!"&ADDRESS(ROW(),COLUMN()-3)) -> 26 | ... KS7: =INDIRECT("RawData!"&ADDRESS(ROW(),COLUMN()-3))
A8: Mrs. Rini Bansal | B8: 9812955220 | C8: https://datastudio.google.com/reporting/8e503f98-b9ea-4967-90be-a092944aa9df | D8: =INDIRECT("RawData!"&ADDRESS(ROW(),1)) -> Aarav Bansal | E8: =INDIRECT("RawData!"&ADDRESS(ROW(),COLUMN()-3)) -> 22 | F8: =INDIRECT("RawData!"&ADDRESS(ROW(),COLUMN()-3)) -> 38 | G8: =INDIRECT("RawData!"&ADDRESS(ROW(),COLUMN()-3)) -> 24 | H8: =INDIRECT("RawData!"&ADDRESS(ROW(),COLUMN()-3)) -> 40 | I8: =INDIRECT("RawData!"&ADDRESS(ROW(),COLUMN()-3)) -> 38 | J8: =INDIRECT("RawData!"&ADDRESS(ROW(),COLUMN()-3)) -> 38 | K8: =INDIRECT("RawData!"&ADDRESS(ROW(),COLUMN()-3)) -> 44 | L8: =INDIRECT("RawData!"&ADDRESS(ROW(),COLUMN()-3)) -> 38 | ... KS8: =INDIRECT("RawData!"&ADDRESS(ROW(),COLUMN()-3))
A9: Mrs. Vandana Gupta | B9: 9416269340 | C9: https://datastudio.google.com/reporting/f1d358de-316e-4db3-ba17-69658dc445d0 | D9: =INDIRECT("RawData!"&ADDRESS(ROW(),1)) -> Aashi Gupta | E9: =INDIRECT("RawData!"&ADDRESS(ROW(),COLUMN()-3)) -> 22 | F9: =INDIRECT("RawData!"&ADDRESS(ROW(),COLUMN()-3)) -> 22 | G9: =INDIRECT("RawData!"&ADDRESS(ROW(),COLUMN()-3)) -> 22 | H9: =INDIRECT("RawData!"&ADDRESS(ROW(),COLUMN()-3)) -> 32 | I9: =INDIRECT("RawData!"&ADDRESS(ROW(),COLUMN()-3)) -> 32 | J9: =INDIRECT("RawData!"&ADDRESS(ROW(),COLUMN()-3)) -> 38 | K9: =INDIRECT("RawData!"&ADDRESS(ROW(),COLUMN()-3)) -> 38 | L9: =INDIRECT("RawData!"&ADDRESS(ROW(),COLUMN()-3)) -> 32 | ... KS9: =INDIRECT("RawData!"&ADDRESS(ROW(),COLUMN()-3))
A10: Mrs. Anu Maken | B10: 9728186516 | C10: https://datastudio.google.com/reporting/430d10b0-8a9e-4805-a87a-c155c302d8bb | D10: =INDIRECT("RawData!"&ADDRESS(ROW(),1)) -> Aashray Maken | E10: =INDIRECT("RawData!"&ADDRESS(ROW(),COLUMN()-3)) -> 14 | F10: =INDIRECT("RawData!"&ADDRESS(ROW(),COLUMN()-3)) -> 30 | G10: =INDIRECT("RawData!"&ADDRESS(ROW(),COLUMN()-3)) -> 18 | H10: =INDIRECT("RawData!"&ADDRESS(ROW(),COLUMN()-3)) -> 28 | I10: =INDIRECT("RawData!"&ADDRESS(ROW(),COLUMN()-3)) -> 20 | J10: =INDIRECT("RawData!"&ADDRESS(ROW(),COLUMN()-3)) -> 18 | K10: =INDIRECT("RawData!"&ADDRESS(ROW(),COLUMN()-3)) -> 30 | L10: =INDIRECT("RawData!"&ADDRESS(ROW(),COLUMN()-3)) -> 30 | ... KS10: =INDIRECT("RawData!"&ADDRESS(ROW(),COLUMN()-3))
A11: Mrs. Aarti Kataria | B11: 9896032633 | C11: https://datastudio.google.com/reporting/8b30ca8a-06b4-450a-ba8e-70395a0d54ee | D11: =INDIRECT("RawData!"&ADDRESS(ROW(),1)) -> Adaa Kataria | E11: =INDIRECT("RawData!"&ADDRESS(ROW(),COLUMN()-3)) -> Absent | F11: =INDIRECT("RawData!"&ADDRESS(ROW(),COLUMN()-3)) -> Absent | G11: =INDIRECT("RawData!"&ADDRESS(ROW(),COLUMN()-3)) -> Absent | H11: =INDIRECT("RawData!"&ADDRESS(ROW(),COLUMN()-3)) -> Absent | I11: =INDIRECT("RawData!"&ADDRESS(ROW(),COLUMN()-3)) -> Absent | J11: =INDIRECT("RawData!"&ADDRESS(ROW(),COLUMN()-3)) -> Absent | K11: =INDIRECT("RawData!"&ADDRESS(ROW(),COLUMN()-3)) -> Absent | L11: =INDIRECT("RawData!"&ADDRESS(ROW(),COLUMN()-3)) -> Absent | ... KS11: =INDIRECT("RawData!"&ADDRESS(ROW(),COLUMN()-3))
A12: Mrs. Shilpi Dhall | B12: 9466854020 | C12: https://lookerstudio.google.com/reporting/7043de87-8507-4587-8f60-5206dc75b4c3 | D12: =INDIRECT("RawData!"&ADDRESS(ROW(),1)) -> Adhiraj Dhall | E12: =INDIRECT("RawData!"&ADDRESS(ROW(),COLUMN()-3)) -> 22 | F12: =INDIRECT("RawData!"&ADDRESS(ROW(),COLUMN()-3)) -> 40 | G12: =INDIRECT("RawData!"&ADDRESS(ROW(),COLUMN()-3)) -> 22 | H12: =INDIRECT("RawData!"&ADDRESS(ROW(),COLUMN()-3)) -> 36 | I12: =INDIRECT("RawData!"&ADDRESS(ROW(),COLUMN()-3)) -> 40 | J12: =INDIRECT("RawData!"&ADDRESS(ROW(),COLUMN()-3)) -> 36 | K12: =INDIRECT("RawData!"&ADDRESS(ROW(),COLUMN()-3)) -> 34 | L12: =INDIRECT("RawData!"&ADDRESS(ROW(),COLUMN()-3)) -> 38 | ... KS12: =INDIRECT("RawData!"&ADDRESS(ROW(),COLUMN()-3))
A13: Mrs. Harpreet kaur | B13: 8684822185 | C13: https://datastudio.google.com/reporting/14a275f8-cf2d-4315-a83f-56a8c4b09f38 | D13: =INDIRECT("RawData!"&ADDRESS(ROW(),1)) -> Agamya Saini | E13: =INDIRECT("RawData!"&ADDRESS(ROW(),COLUMN()-3)) -> Absent | F13: =INDIRECT("RawData!"&ADDRESS(ROW(),COLUMN()-3)) -> Absent | G13: =INDIRECT("RawData!"&ADDRESS(ROW(),COLUMN()-3)) -> Absent | H13: =INDIRECT("RawData!"&ADDRESS(ROW(),COLUMN()-3)) -> Absent | I13: =INDIRECT("RawData!"&ADDRESS(ROW(),COLUMN()-3)) -> Absent | J13: =INDIRECT("RawData!"&ADDRESS(ROW(),COLUMN()-3)) -> Absent | K13: =INDIRECT("RawData!"&ADDRESS(ROW(),COLUMN()-3)) -> Absent | L13: =INDIRECT("RawData!"&ADDRESS(ROW(),COLUMN()-3)) -> Absent | ... KS13: =INDIRECT("RawData!"&ADDRESS(ROW(),COLUMN()-3))
A14: Mrs. Aarti Singh | B14: 7206249087 | C14: https://lookerstudio.google.com/reporting/6ae07695-7c18-45ce-8bcb-ff42d20c5c64 | D14: =INDIRECT("RawData!"&ADDRESS(ROW(),1)) -> Akshat Singh | E14: =INDIRECT("RawData!"&ADDRESS(ROW(),COLUMN()-3)) -> 22 | F14: =INDIRECT("RawData!"&ADDRESS(ROW(),COLUMN()-3)) -> 40 | G14: =INDIRECT("RawData!"&ADDRESS(ROW(),COLUMN()-3)) -> 24 | H14: =INDIRECT("RawData!"&ADDRESS(ROW(),COLUMN()-3)) -> 34 | I14: =INDIRECT("RawData!"&ADDRESS(ROW(),COLUMN()-3)) -> 16 | J14: =INDIRECT("RawData!"&ADDRESS(ROW(),COLUMN()-3)) -> 36 | K14: =INDIRECT("RawData!"&ADDRESS(ROW(),COLUMN()-3)) -> 36 | L14: =INDIRECT("RawData!"&ADDRESS(ROW(),COLUMN()-3)) -> 32 | ... KS14: =INDIRECT("RawData!"&ADDRESS(ROW(),COLUMN()-3))
A15: Mr. Amit Goel | B15: 9541222211 | C15: https://lookerstudio.google.com/reporting/2a2879dc-c53b-4f71-af35-efb10d702071 | D15: =INDIRECT("RawData!"&ADDRESS(ROW(),1)) -> Ameya Goel | E15: =INDIRECT("RawData!"&ADDRESS(ROW(),COLUMN()-3)) -> Absent | F15: =INDIRECT("RawData!"&ADDRESS(ROW(),COLUMN()-3)) -> Absent | G15: =INDIRECT("RawData!"&ADDRESS(ROW(),COLUMN()-3)) -> Absent | H15: =INDIRECT("RawData!"&ADDRESS(ROW(),COLUMN()-3)) -> Absent | I15: =INDIRECT("RawData!"&ADDRESS(ROW(),COLUMN()-3)) -> Absent | J15: =INDIRECT("RawData!"&ADDRESS(ROW(),COLUMN()-3)) -> Absent | K15: =INDIRECT("RawData!"&ADDRESS(ROW(),COLUMN()-3)) -> Absent | L15: =INDIRECT("RawData!"&ADDRESS(ROW(),COLUMN()-3)) -> Absent | ... KS15: =INDIRECT("RawData!"&ADDRESS(ROW(),COLUMN()-3))
A16: Mrs. Megha Arora | B16: 9896164643 | C16: https://lookerstudio.google.com/reporting/ff81dbbe-5f0f-41a0-8273-a93e22db8041 | D16: =INDIRECT("RawData!"&ADDRESS(ROW(),1)) -> Anay Arora | E16: =INDIRECT("RawData!"&ADDRESS(ROW(),COLUMN()-3)) -> 16 | F16: =INDIRECT("RawData!"&ADDRESS(ROW(),COLUMN()-3)) -> 28 | G16: =INDIRECT("RawData!"&ADDRESS(ROW(),COLUMN()-3)) -> 16 | H16: =INDIRECT("RawData!"&ADDRESS(ROW(),COLUMN()-3)) -> 26 | I16: =INDIRECT("RawData!"&ADDRESS(ROW(),COLUMN()-3)) -> 22 | J16: =INDIRECT("RawData!"&ADDRESS(ROW(),COLUMN()-3)) -> 24 | K16: =INDIRECT("RawData!"&ADDRESS(ROW(),COLUMN()-3)) -> 30 | L16: =INDIRECT("RawData!"&ADDRESS(ROW(),COLUMN()-3)) -> 26 | ... KS16: =INDIRECT("RawData!"&ADDRESS(ROW(),COLUMN()-3))
A17: Mr. Sachin Goel | B17: 7876611111 | C17: https://lookerstudio.google.com/reporting/a42666dc-19fa-4c1b-b17a-12e033ddec56 | D17: =INDIRECT("RawData!"&ADDRESS(ROW(),1)) -> Arnav Goel | E17: =INDIRECT("RawData!"&ADDRESS(ROW(),COLUMN()-3)) -> 24 | F17: =INDIRECT("RawData!"&ADDRESS(ROW(),COLUMN()-3)) -> 38 | G17: =INDIRECT("RawData!"&ADDRESS(ROW(),COLUMN()-3)) -> 24 | H17: =INDIRECT("RawData!"&ADDRESS(ROW(),COLUMN()-3)) -> 38 | I17: =INDIRECT("RawData!"&ADDRESS(ROW(),COLUMN()-3)) -> 34 | J17: =INDIRECT("RawData!"&ADDRESS(ROW(),COLUMN()-3)) -> 30 | K17: =INDIRECT("RawData!"&ADDRESS(ROW(),COLUMN()-3)) -> 32 | L17: =INDIRECT("RawData!"&ADDRESS(ROW(),COLUMN()-3)) -> 38 | ... KS17: =INDIRECT("RawData!"&ADDRESS(ROW(),COLUMN()-3))
... A19: Mrs. Mansi Saxena | B19: 7206088590 | C19: https://lookerstudio.google.com/reporting/640a40d2-25b8-40f4-91d4-af283a2ca7ea | D19: =INDIRECT("RawData!"&ADDRESS(ROW(),1)) -> Arnav Saxena | E19: =INDIRECT("RawData!"&ADDRESS(ROW(),COLUMN()-3)) -> 22 | F19: =INDIRECT("RawData!"&ADDRESS(ROW(),COLUMN()-3)) -> 38 | G19: =INDIRECT("RawData!"&ADDRESS(ROW(),COLUMN()-3)) -> 24 | H19: =INDIRECT("RawData!"&ADDRESS(ROW(),COLUMN()-3)) -> 40 | I19: =INDIRECT("RawData!"&ADDRESS(ROW(),COLUMN()-3)) -> 38 | J19: =INDIRECT("RawData!"&ADDRESS(ROW(),COLUMN()-3)) -> 38 | K19: =INDIRECT("RawData!"&ADDRESS(ROW(),COLUMN()-3)) -> 44 | L19: =INDIRECT("RawData!"&ADDRESS(ROW(),COLUMN()-3)) -> 38 | ... KS19: =INDIRECT("RawData!"&ADDRESS(ROW(),COLUMN()-3))
A20: Mrs. Neha Aggarwal | B20: 9996617210, 9896017210 | C20: https://lookerstudio.google.com/reporting/bca936b3-0681-4eee-a0d1-5d0c5b1e3509 | D20: =INDIRECT("RawData!"&ADDRESS(ROW(),1)) -> Atharv Aggarwal | E20: =INDIRECT("RawData!"&ADDRESS(ROW(),COLUMN()-3)) -> 20 | F20: =INDIRECT("RawData!"&ADDRESS(ROW(),COLUMN()-3)) -> 36 | G20: =INDIRECT("RawData!"&ADDRESS(ROW(),COLUMN()-3)) -> 20 | H20: =INDIRECT("RawData!"&ADDRESS(ROW(),COLUMN()-3)) -> 38 | I20: =INDIRECT("RawData!"&ADDRESS(ROW(),COLUMN()-3)) -> 36 | J20: =INDIRECT("RawData!"&ADDRESS(ROW(),COLUMN()-3)) -> 34 | K20: =INDIRECT("RawData!"&ADDRESS(ROW(),COLUMN()-3)) -> 44 | L20: =INDIRECT("RawData!"&ADDRESS(ROW(),COLUMN()-3)) -> 36 | ... KS20: =INDIRECT("RawData!"&ADDRESS(ROW(),COLUMN()-3))
A21: Mrs. Nitika Chhabra | B21: 7988106247 | C21: https://lookerstudio.google.com/reporting/d3fb6689-a385-45f6-a0f4-0d524f13421d | D21: =INDIRECT("RawData!"&ADDRESS(ROW(),1)) -> Avni Chhabra | E21: =INDIRECT("RawData!"&ADDRESS(ROW(),COLUMN()-3)) -> 22 | F21: =INDIRECT("RawData!"&ADDRESS(ROW(),COLUMN()-3)) -> 30 | G21: =INDIRECT("RawData!"&ADDRESS(ROW(),COLUMN()-3)) -> 24 | H21: =INDIRECT("RawData!"&ADDRESS(ROW(),COLUMN()-3)) -> 36 | I21: =INDIRECT("RawData!"&ADDRESS(ROW(),COLUMN()-3)) -> 28 | J21: =INDIRECT("RawData!"&ADDRESS(ROW(),COLUMN()-3)) -> 24 | K21: =INDIRECT("RawData!"&ADDRESS(ROW(),COLUMN()-3)) -> 32 | L21: =INDIRECT("RawData!"&ADDRESS(ROW(),COLUMN()-3)) -> 28 | ... KS21: =INDIRECT("RawData!"&ADDRESS(ROW(),COLUMN()-3))
A22: Mr. Gaurav Guglani | B22: 9812203460 | C22: https://lookerstudio.google.com/reporting/f68a8a51-9f34-4363-810f-3e73ca551560 | D22: =INDIRECT("RawData!"&ADDRESS(ROW(),1)) -> Ayaan Guglani | E22: =INDIRECT("RawData!"&ADDRESS(ROW(),COLUMN()-3)) -> 22 | F22: =INDIRECT("RawData!"&ADDRESS(ROW(),COLUMN()-3)) -> 38 | G22: =INDIRECT("RawData!"&ADDRESS(ROW(),COLUMN()-3)) -> 24 | H22: =INDIRECT("RawData!"&ADDRESS(ROW(),COLUMN()-3)) -> 36 | I22: =INDIRECT("RawData!"&ADDRESS(ROW(),COLUMN()-3)) -> 38 | J22: =INDIRECT("RawData!"&ADDRESS(ROW(),COLUMN()-3)) -> 32 | K22: =INDIRECT("RawData!"&ADDRESS(ROW(),COLUMN()-3)) -> 38 | L22: =INDIRECT("RawData!"&ADDRESS(ROW(),COLUMN()-3)) -> 38 | ... KS22: =INDIRECT("RawData!"&ADDRESS(ROW(),COLUMN()-3))
A23: Mrs. Harpreet Kaur | B23: 9896157477 | C23: https://lookerstudio.google.com/reporting/2d8f68a8-a6eb-413a-b73c-db0cf71c6e94 | D23: =INDIRECT("RawData!"&ADDRESS(ROW(),1)) -> Ayaan Singh | E23: =INDIRECT("RawData!"&ADDRESS(ROW(),COLUMN()-3)) -> 20 | F23: =INDIRECT("RawData!"&ADDRESS(ROW(),COLUMN()-3)) -> 40 | G23: =INDIRECT("RawData!"&ADDRESS(ROW(),COLUMN()-3)) -> 24 | H23: =INDIRECT("RawData!"&ADDRESS(ROW(),COLUMN()-3)) -> 40 | I23: =INDIRECT("RawData!"&ADDRESS(ROW(),COLUMN()-3)) -> 34 | J23: =INDIRECT("RawData!"&ADDRESS(ROW(),COLUMN()-3)) -> 38 | K23: =INDIRECT("RawData!"&ADDRESS(ROW(),COLUMN()-3)) -> 45 | L23: =INDIRECT("RawData!"&ADDRESS(ROW(),COLUMN()-3)) -> 36 | ... KS23: =INDIRECT("RawData!"&ADDRESS(ROW(),COLUMN()-3))
A24: Mr. Subodh Kumar | B24: 7082290040 | C24: https://lookerstudio.google.com/reporting/4f34172b-eb6c-445b-b904-9ab92c92f215 | D24: =INDIRECT("RawData!"&ADDRESS(ROW(),1)) -> Ayush Kumar | E24: =INDIRECT("RawData!"&ADDRESS(ROW(),COLUMN()-3)) -> 10 | F24: =INDIRECT("RawData!"&ADDRESS(ROW(),COLUMN()-3)) -> 20 | G24: =INDIRECT("RawData!"&ADDRESS(ROW(),COLUMN()-3)) -> 16 | H24: =INDIRECT("RawData!"&ADDRESS(ROW(),COLUMN()-3)) -> 18 | I24: =INDIRECT("RawData!"&ADDRESS(ROW(),COLUMN()-3)) -> 16 | J24: =INDIRECT("RawData!"&ADDRESS(ROW(),COLUMN()-3)) -> 22 | K24: =INDIRECT("RawData!"&ADDRESS(ROW(),COLUMN()-3)) -> 18 | L24: =INDIRECT("RawData!"&ADDRESS(ROW(),COLUMN()-3)) -> 16 | ... KS24: =INDIRECT("RawData!"&ADDRESS(ROW(),COLUMN()-3))
A25: Mrs. Kavita Katoch | B25: 9467814860 | C25: https://lookerstudio.google.com/reporting/c9d95359-3903-4808-af03-b35861282f6a | D25: =INDIRECT("RawData!"&ADDRESS(ROW(),1)) -> Bhavik Katoch | E25: =INDIRECT("RawData!"&ADDRESS(ROW(),COLUMN()-3)) -> 22 | F25: =INDIRECT("RawData!"&ADDRESS(ROW(),COLUMN()-3)) -> 36 | G25: =INDIRECT("RawData!"&ADDRESS(ROW(),COLUMN()-3)) -> 24 | H25: =INDIRECT("RawData!"&ADDRESS(ROW(),COLUMN()-3)) -> 36 | I25: =INDIRECT("RawData!"&ADDRESS(ROW(),COLUMN()-3)) -> 38 | J25: =INDIRECT("RawData!"&ADDRESS(ROW(),COLUMN()-3)) -> 34 | K25: =INDIRECT("RawData!"&ADDRESS(ROW(),COLUMN()-3)) -> 42 | L25: =INDIRECT("RawData!"&ADDRESS(ROW(),COLUMN()-3)) -> 38 | ... KS25: =INDIRECT("RawData!"&ADDRESS(ROW(),COLUMN()-3))
A26: Mrs. Renu Chawla | B26: 8053206613 | C26: https://lookerstudio.google.com/reporting/0cf4ef26-4dfd-4b2e-8d9a-7f387b0ca0c3 | D26: =INDIRECT("RawData!"&ADDRESS(ROW(),1)) -> Bhavya Chawla | E26: =INDIRECT("RawData!"&ADDRESS(ROW(),COLUMN()-3)) -> 22 | F26: =INDIRECT("RawData!"&ADDRESS(ROW(),COLUMN()-3)) -> 24 | G26: =INDIRECT("RawData!"&ADDRESS(ROW(),COLUMN()-3)) -> 20 | H26: =INDIRECT("RawData!"&ADDRESS(ROW(),COLUMN()-3)) -> 36 | I26: =INDIRECT("RawData!"&ADDRESS(ROW(),COLUMN()-3)) -> 40 | J26: =INDIRECT("RawData!"&ADDRESS(ROW(),COLUMN()-3)) -> 30 | K26: =INDIRECT("RawData!"&ADDRESS(ROW(),COLUMN()-3)) -> 32 | L26: =INDIRECT("RawData!"&ADDRESS(ROW(),COLUMN()-3)) -> 38 | ... KS26: =INDIRECT("RawData!"&ADDRESS(ROW(),COLUMN()-3))
A27: Mr. Vijay Pal Chauhan | B27: 8222876492 | C27: https://lookerstudio.google.com/reporting/741130cd-c3fd-479a-9172-30dfca859d35 | D27: =INDIRECT("RawData!"&ADDRESS(ROW(),1)) -> Bhuvi Chauhan | E27: =INDIRECT("RawData!"&ADDRESS(ROW(),COLUMN()-3)) -> 20 | F27: =INDIRECT("RawData!"&ADDRESS(ROW(),COLUMN()-3)) -> 40 | G27: =INDIRECT("RawData!"&ADDRESS(ROW(),COLUMN()-3)) -> 24 | H27: =INDIRECT("RawData!"&ADDRESS(ROW(),COLUMN()-3)) -> 40 | I27: =INDIRECT("RawData!"&ADDRESS(ROW(),COLUMN()-3)) -> 38 | J27: =INDIRECT("RawData!"&ADDRESS(ROW(),COLUMN()-3)) -> 38 | K27: =INDIRECT("RawData!"&ADDRESS(ROW(),COLUMN()-3)) -> 36 | L27: =INDIRECT("RawData!"&ADDRESS(ROW(),COLUMN()-3)) -> 40 | ... KS27: =INDIRECT("RawData!"&ADDRESS(ROW(),COLUMN()-3))
A28: Mrs. Rajni Sehgal | B28: 9017802483 | C28: https://lookerstudio.google.com/reporting/ecab8d0c-2aa9-481d-a207-47eed87756b1 | D28: =INDIRECT("RawData!"&ADDRESS(ROW(),1)) -> Chahat Sehgal | E28: =INDIRECT("RawData!"&ADDRESS(ROW(),COLUMN()-3)) -> Absent | F28: =INDIRECT("RawData!"&ADDRESS(ROW(),COLUMN()-3)) -> 16 | G28: =INDIRECT("RawData!"&ADDRESS(ROW(),COLUMN()-3)) -> 16 | H28: =INDIRECT("RawData!"&ADDRESS(ROW(),COLUMN()-3)) -> 24 | I28: =INDIRECT("RawData!"&ADDRESS(ROW(),COLUMN()-3)) -> 28 | J28: =INDIRECT("RawData!"&ADDRESS(ROW(),COLUMN()-3)) -> 16 | K28: =INDIRECT("RawData!"&ADDRESS(ROW(),COLUMN()-3)) -> 30 | L28: =INDIRECT("RawData!"&ADDRESS(ROW(),COLUMN()-3)) -> 16 | ... KS28: =INDIRECT("RawData!"&ADDRESS(ROW(),COLUMN()-3))
A29: Mr. Mandeep Umrao | B29: 9466717064 , 9729588502 | C29: https://lookerstudio.google.com/reporting/f827dbdc-0aef-4a40-9529-9161efc2615a | D29: =INDIRECT("RawData!"&ADDRESS(ROW(),1)) -> Chhavi Saini | E29: =INDIRECT("RawData!"&ADDRESS(ROW(),COLUMN()-3)) -> Absent | F29: =INDIRECT("RawData!"&ADDRESS(ROW(),COLUMN()-3)) -> Absent | G29: =INDIRECT("RawData!"&ADDRESS(ROW(),COLUMN()-3)) -> Absent | H29: =INDIRECT("RawData!"&ADDRESS(ROW(),COLUMN()-3)) -> Absent | I29: =INDIRECT("RawData!"&ADDRESS(ROW(),COLUMN()-3)) -> Absent | J29: =INDIRECT("RawData!"&ADDRESS(ROW(),COLUMN()-3)) -> Absent | K29: =INDIRECT("RawData!"&ADDRESS(ROW(),COLUMN()-3)) -> Absent | L29: =INDIRECT("RawData!"&ADDRESS(ROW(),COLUMN()-3)) -> Absent | ... KS29: =INDIRECT("RawData!"&ADDRESS(ROW(),COLUMN()-3))
A30: Mrs. Rashmi Julka | B30: 9991990856 | C30: https://lookerstudio.google.com/reporting/067140c2-6bc3-43e7-a5eb-673cdfa9b7b5 | D30: =INDIRECT("RawData!"&ADDRESS(ROW(),1)) -> Daksh Julka | E30: =INDIRECT("RawData!"&ADDRESS(ROW(),COLUMN()-3)) -> 16 | F30: =INDIRECT("RawData!"&ADDRESS(ROW(),COLUMN()-3)) -> 34 | G30: =INDIRECT("RawData!"&ADDRESS(ROW(),COLUMN()-3)) -> 18 | H30: =INDIRECT("RawData!"&ADDRESS(ROW(),COLUMN()-3)) -> 36 | I30: =INDIRECT("RawData!"&ADDRESS(ROW(),COLUMN()-3)) -> 28 | J30: =INDIRECT("RawData!"&ADDRESS(ROW(),COLUMN()-3)) -> 30 | K30: =INDIRECT("RawData!"&ADDRESS(ROW(),COLUMN()-3)) -> 34 | L30: =INDIRECT("RawData!"&ADDRESS(ROW(),COLUMN()-3)) -> 28 | ... KS30: =INDIRECT("RawData!"&ADDRESS(ROW(),COLUMN()-3))
A31: Mrs. Jatinder Nayar | B31: 8950538980 | C31: https://lookerstudio.google.com/reporting/3a10ed55-5c7c-4541-8f6c-b949bc7f8960 | D31: =INDIRECT("RawData!"&ADDRESS(ROW(),1)) -> Devishee Nayar | E31: =INDIRECT("RawData!"&ADDRESS(ROW(),COLUMN()-3)) -> 22 | F31: =INDIRECT("RawData!"&ADDRESS(ROW(),COLUMN()-3)) -> 40 | G31: =INDIRECT("RawData!"&ADDRESS(ROW(),COLUMN()-3)) -> 24 | H31: =INDIRECT("RawData!"&ADDRESS(ROW(),COLUMN()-3)) -> 40 | I31: =INDIRECT("RawData!"&ADDRESS(ROW(),COLUMN()-3)) -> 36 | J31: =INDIRECT("RawData!"&ADDRESS(ROW(),COLUMN()-3)) -> Absent | K31: =INDIRECT("RawData!"&ADDRESS(ROW(),COLUMN()-3)) -> Absent | L31: =INDIRECT("RawData!"&ADDRESS(ROW(),COLUMN()-3)) -> Absent | ... KS31: =INDIRECT("RawData!"&ADDRESS(ROW(),COLUMN()-3))
A32: Mr. Manish Gupta | B32: 9467387110 | C32: https://lookerstudio.google.com/reporting/ac60c508-f9c4-49d1-8413-57fd1b986a3f | D32: =INDIRECT("RawData!"&ADDRESS(ROW(),1)) -> Devishi Gupta | E32: =INDIRECT("RawData!"&ADDRESS(ROW(),COLUMN()-3)) -> 24 | F32: =INDIRECT("RawData!"&ADDRESS(ROW(),COLUMN()-3)) -> 40 | G32: =INDIRECT("RawData!"&ADDRESS(ROW(),COLUMN()-3)) -> 24 | H32: =INDIRECT("RawData!"&ADDRESS(ROW(),COLUMN()-3)) -> 38 | I32: =INDIRECT("RawData!"&ADDRESS(ROW(),COLUMN()-3)) -> 40 | J32: =INDIRECT("RawData!"&ADDRESS(ROW(),COLUMN()-3)) -> 36 | K32: =INDIRECT("RawData!"&ADDRESS(ROW(),COLUMN()-3)) -> 36 | L32: =INDIRECT("RawData!"&ADDRESS(ROW(),COLUMN()-3)) -> 40 | ... KS32: =INDIRECT("RawData!"&ADDRESS(ROW(),COLUMN()-3))
A33: Mrs. Amarjot Kaur | B33: 9068227877 | C33: https://datastudio.google.com/reporting/f7937078-05e2-41c3-88aa-816894b8787c | D33: =INDIRECT("RawData!"&ADDRESS(ROW(),1)) -> Fateh Partap Singh | E33: =INDIRECT("RawData!"&ADDRESS(ROW(),COLUMN()-3)) -> Absent | F33: =INDIRECT("RawData!"&ADDRESS(ROW(),COLUMN()-3)) -> Absent | G33: =INDIRECT("RawData!"&ADDRESS(ROW(),COLUMN()-3)) -> Absent | H33: =INDIRECT("RawData!"&ADDRESS(ROW(),COLUMN()-3)) -> Absent | I33: =INDIRECT("RawData!"&ADDRESS(ROW(),COLUMN()-3)) -> Absent | J33: =INDIRECT("RawData!"&ADDRESS(ROW(),COLUMN()-3)) -> Absent | K33: =INDIRECT("RawData!"&ADDRESS(ROW(),COLUMN()-3)) -> Absent | L33: =INDIRECT("RawData!"&ADDRESS(ROW(),COLUMN()-3)) -> Absent | ... KS33: =INDIRECT("RawData!"&ADDRESS(ROW(),COLUMN()-3))
A34: Mrs. RamandeepKaur | B34: 9896942375 | C34: https://lookerstudio.google.com/reporting/82ec907e-6dca-4545-b256-460b91406454 | D34: =INDIRECT("RawData!"&ADDRESS(ROW(),1)) -> Japnidh Singh | E34: =INDIRECT("RawData!"&ADDRESS(ROW(),COLUMN()-3)) -> 24 | F34: =INDIRECT("RawData!"&ADDRESS(ROW(),COLUMN()-3)) -> 40 | G34: =INDIRECT("RawData!"&ADDRESS(ROW(),COLUMN()-3)) -> 24 | H34: =INDIRECT("RawData!"&ADDRESS(ROW(),COLUMN()-3)) -> 40 | I34: =INDIRECT("RawData!"&ADDRESS(ROW(),COLUMN()-3)) -> 36 | J34: =INDIRECT("RawData!"&ADDRESS(ROW(),COLUMN()-3)) -> 36 | K34: =INDIRECT("RawData!"&ADDRESS(ROW(),COLUMN()-3)) -> 38 | L34: =INDIRECT("RawData!"&ADDRESS(ROW(),COLUMN()-3)) -> 40 | ... KS34: =INDIRECT("RawData!"&ADDRESS(ROW(),COLUMN()-3))
A35: Mrs. Gurjeet Kaur | B35: 9802222201 , 9802222223 | C35: https://lookerstudio.google.com/reporting/853c32df-73f6-40b4-be48-9eebfc4ac037 | D35: =INDIRECT("RawData!"&ADDRESS(ROW(),1)) -> Jaskeerat Kaur | E35: =INDIRECT("RawData!"&ADDRESS(ROW(),COLUMN()-3)) -> 22 | F35: =INDIRECT("RawData!"&ADDRESS(ROW(),COLUMN()-3)) -> 40 | G35: =INDIRECT("RawData!"&ADDRESS(ROW(),COLUMN()-3)) -> 22 | H35: =INDIRECT("RawData!"&ADDRESS(ROW(),COLUMN()-3)) -> 40 | I35: =INDIRECT("RawData!"&ADDRESS(ROW(),COLUMN()-3)) -> 38 | J35: =INDIRECT("RawData!"&ADDRESS(ROW(),COLUMN()-3)) -> 38 | K35: =INDIRECT("RawData!"&ADDRESS(ROW(),COLUMN()-3)) -> 40 | L35: =INDIRECT("RawData!"&ADDRESS(ROW(),COLUMN()-3)) -> 36 | ... KS35: =INDIRECT("RawData!"&ADDRESS(ROW(),COLUMN()-3))
A36: Mrs. Sangeeta Vasoya | B36: 9416553499 | C36: https://lookerstudio.google.com/reporting/df451d53-a67e-4ea1-bd4a-ec79b097910f | D36: =INDIRECT("RawData!"&ADDRESS(ROW(),1)) -> Jigar | E36: =INDIRECT("RawData!"&ADDRESS(ROW(),COLUMN()-3)) -> Absent | F36: =INDIRECT("RawData!"&ADDRESS(ROW(),COLUMN()-3)) -> Absent | G36: =INDIRECT("RawData!"&ADDRESS(ROW(),COLUMN()-3)) -> Absent | H36: =INDIRECT("RawData!"&ADDRESS(ROW(),COLUMN()-3)) -> Absent | I36: =INDIRECT("RawData!"&ADDRESS(ROW(),COLUMN()-3)) -> Absent | J36: =INDIRECT("RawData!"&ADDRESS(ROW(),COLUMN()-3)) -> 22 | K36: =INDIRECT("RawData!"&ADDRESS(ROW(),COLUMN()-3)) -> 24 | L36: =INDIRECT("RawData!"&ADDRESS(ROW(),COLUMN()-3)) -> 16 | ... KS36: =INDIRECT("RawData!"&ADDRESS(ROW(),COLUMN()-3))
A37: Mrs. Preeti Chadha | B37: 9034883180 | C37: https://datastudio.google.com/reporting/9e8c0c36-8e6f-4688-ba78-f7458f7e9339 | D37: =INDIRECT("RawData!"&ADDRESS(ROW(),1)) -> Jivanshi | E37: =INDIRECT("RawData!"&ADDRESS(ROW(),COLUMN()-3)) -> Absent | F37: =INDIRECT("RawData!"&ADDRESS(ROW(),COLUMN()-3)) -> Absent | G37: =INDIRECT("RawData!"&ADDRESS(ROW(),COLUMN()-3)) -> Absent | H37: =INDIRECT("RawData!"&ADDRESS(ROW(),COLUMN()-3)) -> Absent | I37: =INDIRECT("RawData!"&ADDRESS(ROW(),COLUMN()-3)) -> Absent | J37: =INDIRECT("RawData!"&ADDRESS(ROW(),COLUMN()-3)) -> Absent | K37: =INDIRECT("RawData!"&ADDRESS(ROW(),COLUMN()-3)) -> Absent | L37: =INDIRECT("RawData!"&ADDRESS(ROW(),COLUMN()-3)) -> Absent | ... KS37: =INDIRECT("RawData!"&ADDRESS(ROW(),COLUMN()-3))
A38: Mrs. Monica Chauhan | B38: 9817574525 | C38: https://lookerstudio.google.com/reporting/275710da-13b2-4bf7-9b9c-e2f7686768d0 | D38: =INDIRECT("RawData!"&ADDRESS(ROW(),1)) -> Kanishk Singh | E38: =INDIRECT("RawData!"&ADDRESS(ROW(),COLUMN()-3)) -> 20 | F38: =INDIRECT("RawData!"&ADDRESS(ROW(),COLUMN()-3)) -> 24 | G38: =INDIRECT("RawData!"&ADDRESS(ROW(),COLUMN()-3)) -> 18 | H38: =INDIRECT("RawData!"&ADDRESS(ROW(),COLUMN()-3)) -> 30 | I38: =INDIRECT("RawData!"&ADDRESS(ROW(),COLUMN()-3)) -> 16 | J38: =INDIRECT("RawData!"&ADDRESS(ROW(),COLUMN()-3)) -> 38 | K38: =INDIRECT("RawData!"&ADDRESS(ROW(),COLUMN()-3)) -> 32 | L38: =INDIRECT("RawData!"&ADDRESS(ROW(),COLUMN()-3)) -> 16 | ... KS38: =INDIRECT("RawData!"&ADDRESS(ROW(),COLUMN()-3))
A39: Mr. Mohit Gupta | B39: 7206066000 | C39: https://lookerstudio.google.com/reporting/e6da509a-6f9d-4452-a3af-4d31c3c5af79 | D39: =INDIRECT("RawData!"&ADDRESS(ROW(),1)) -> Kartik Gupta | E39: =INDIRECT("RawData!"&ADDRESS(ROW(),COLUMN()-3)) -> 24 | F39: =INDIRECT("RawData!"&ADDRESS(ROW(),COLUMN()-3)) -> 40 | G39: =INDIRECT("RawData!"&ADDRESS(ROW(),COLUMN()-3)) -> 24 | H39: =INDIRECT("RawData!"&ADDRESS(ROW(),COLUMN()-3)) -> 38 | I39: =INDIRECT("RawData!"&ADDRESS(ROW(),COLUMN()-3)) -> 40 | J39: =INDIRECT("RawData!"&ADDRESS(ROW(),COLUMN()-3)) -> 38 | K39: =INDIRECT("RawData!"&ADDRESS(ROW(),COLUMN()-3)) -> 45 | L39: =INDIRECT("RawData!"&ADDRESS(ROW(),COLUMN()-3)) -> 38 | ... KS39: =INDIRECT("RawData!"&ADDRESS(ROW(),COLUMN()-3))
A40: Mrs. Shuchi Batra | B40: 9416937002 | C40: https://lookerstudio.google.com/reporting/0285bee3-7a67-416d-b088-d1c73f4a1905 | D40: =INDIRECT("RawData!"&ADDRESS(ROW(),1)) -> Kavish Batra | E40: =INDIRECT("RawData!"&ADDRESS(ROW(),COLUMN()-3)) -> 20 | F40: =INDIRECT("RawData!"&ADDRESS(ROW(),COLUMN()-3)) -> 34 | G40: =INDIRECT("RawData!"&ADDRESS(ROW(),COLUMN()-3)) -> 24 | H40: =INDIRECT("RawData!"&ADDRESS(ROW(),COLUMN()-3)) -> 38 | I40: =INDIRECT("RawData!"&ADDRESS(ROW(),COLUMN()-3)) -> 40 | J40: =INDIRECT("RawData!"&ADDRESS(ROW(),COLUMN()-3)) -> 36 | K40: =INDIRECT("RawData!"&ADDRESS(ROW(),COLUMN()-3)) -> 38 | L40: =INDIRECT("RawData!"&ADDRESS(ROW(),COLUMN()-3)) -> 40 | ... KS40: =INDIRECT("RawData!"&ADDRESS(ROW(),COLUMN()-3))
A41: Mrs. Shweta Gupta | B41: 8168346179 | C41: https://lookerstudio.google.com/reporting/3cea9e1c-9f7c-4b4e-b08d-ef0333d3d7e2 | D41: =INDIRECT("RawData!"&ADDRESS(ROW(),1)) -> Keshav Gupta | E41: =INDIRECT("RawData!"&ADDRESS(ROW(),COLUMN()-3)) -> 24 | F41: =INDIRECT("RawData!"&ADDRESS(ROW(),COLUMN()-3)) -> 30 | G41: =INDIRECT("RawData!"&ADDRESS(ROW(),COLUMN()-3)) -> 24 | H41: =INDIRECT("RawData!"&ADDRESS(ROW(),COLUMN()-3)) -> 34 | I41: =INDIRECT("RawData!"&ADDRESS(ROW(),COLUMN()-3)) -> 34 | J41: =INDIRECT("RawData!"&ADDRESS(ROW(),COLUMN()-3)) -> 34 | K41: =INDIRECT("RawData!"&ADDRESS(ROW(),COLUMN()-3)) -> 42 | L41: =INDIRECT("RawData!"&ADDRESS(ROW(),COLUMN()-3)) -> 32 | ... KS41: =INDIRECT("RawData!"&ADDRESS(ROW(),COLUMN()-3))
...

Sheet WhatsApp Send Log
A1: Timestamp | B1: Test Number | C1: Test Column | D1: Test Date | E1: Student Name | F1: Phone Number | G1: Dashboard Link | H1: Status | I1: Message ID | J1: Error (if any) | K1: Protected
A2: 46119.478 | B2: 1 | C2: E1 | D2: 46118 | E2: Aabhav Aggarwal | F2: 919416177674 | G2: https://lookerstudio.google.com/reporting/b56c7bd8-a855-4974-8118-cd4cd2779f96 | H2: SENT | I2: wamid.HBgMOTE5NDE2MTc3Njc0FQIAERgSMDRFODAwODVCMERBNzYzRTY0AA== | K2: No
A3: 46119.478 | B3: 1 | C3: E1 | D3: 46118 | E3: Aarav Bansal | F3: 919812955220 | G3: https://lookerstudio.google.com/reporting/8e503f98-b9ea-4967-90be-a092944aa9df | H3: SENT | I3: wamid.HBgMOTE5ODEyOTU1MjIwFQIAERgSRTY3N0QwNzlDNEQwMkZENzJGAA== | K3: No
A4: 46119.478 | B4: 1 | C4: E1 | D4: 46118 | E4: Aarav Gupta | F4: 919466335774 | G4: https://lookerstudio.google.com/reporting/75329970-6ac0-472c-9d08-b8ff8687e0b6 | H4: SENT - ABSENT | K4: No
A5: 46119.478 | B5: 1 | C5: E1 | D5: 46118 | E5: Aashi Gupta | F5: 919416269340 | G5: https://lookerstudio.google.com/reporting/adf66053-e2a6-463b-828b-99f4a2bcf38d | H5: SENT | I5: wamid.HBgMOTE5NDE2MjY5MzQwFQIAERgSQ0U2RDUxMDVBNjVDMDNFMUY1AA== | K5: No
A6: 46119.479 | B6: 1 | C6: E1 | D6: 46118 | E6: Aabhav Aggarwal | F6: 919416177674 | G6: https://lookerstudio.google.com/reporting/b56c7bd8-a855-4974-8118-cd4cd2779f96 | H6: SENT | I6: wamid.HBgMOTE5NDE2MTc3Njc0FQIAERgSOThDNjJGNzdCM0NFRkFEMzBBAA== | K6: No
A7: 46119.479 | B7: 1 | C7: E1 | D7: 46118 | E7: Aarav Bansal | F7: 919812955220 | G7: https://lookerstudio.google.com/reporting/8e503f98-b9ea-4967-90be-a092944aa9df | H7: SENT | I7: wamid.HBgMOTE5ODEyOTU1MjIwFQIAERgSQzIxRDdGNjQxMDlFMEE5RkE1AA== | K7: No
A8: 46119.479 | B8: 1 | C8: E1 | D8: 46118 | E8: Aarav Gupta | F8: 919466335774 | G8: https://lookerstudio.google.com/reporting/75329970-6ac0-472c-9d08-b8ff8687e0b6 | H8: SENT - ABSENT | K8: No
A9: 46119.479 | B9: 1 | C9: E1 | D9: 46118 | E9: Aashi Gupta | F9: 919416269340 | G9: https://lookerstudio.google.com/reporting/adf66053-e2a6-463b-828b-99f4a2bcf38d | H9: SENT | I9: wamid.HBgMOTE5NDE2MjY5MzQwFQIAERgSQ0M2MEMyNTNDRDFDQjczRTgwAA== | K9: No
